Workbook

Sheet 설정_및_규칙
A1: 항목 | B1: 내용
A2: §0.5 제품 설정 블록 (승인분)
A3: PRODUCT | B3: RemoteView
A4: PREFIX | B4: RV
A5: SOURCE_ROOT | B5: RAG_RV_data/ (docs/chunks export 2026-07-10, indexed 2026-07-01~02)
A6: HELPDESK_BASE | B6: https://help.rview.com/hc/ko/ — 링크로만 존재, 코퍼스 미인입 (인입 누락 리포트 후보)
A7: ACL_DEFAULT | B7: 공개
A9: 부가 조항 (설계본부 확정)
A10: ⑥ 보일러플레이트 규칙 | B10: 발췌·사실 필드는 본문 문장만. 제외: 내비게이션·바로가기·서비스 가동배너·구매/기술지원 전화·푸터(Tel/FAX/주소/사업자번호/저작권)
A11: ⑧ 시점 앵커 규칙(B2 검수 명문화) | B11: 가격·할인율·기간 등 변동성 수치를 포함하는 단위 전건에 [시점 앵커: 인덱싱일] 명기. 정본 개정 시 재검토 대상 표식. 완료 보고는 적용 N / 불요 N(수치 부재) 분리 계리
A12: ⑨ 약관·SLA 시점 장치 | B12: 약관 전건 [시행 기준: 2021-02-16] 명기 (부칙 제1조 실측)
A13: 트랙 | B13: 코퍼스판 단독 트랙 — 코퍼스 내 문서 자체가 정본(설계본부 확정 1). 작업 기준: 실측 chunks 5,139
A15: 시스템팀 공유 후보 목록
A16: 1호 | B16: docs.chunk_count 메타 합계 4,594 ≠ 실제 청크 5,139 (+545, 35문서) — export 정합성 이슈
A17: 2호 | B17: help.rview.com 헬프데스크 미인입 — 링크로만 존재. 인입 누락 리포트 후보
A18: 3호 | B18: 반응형 3중 렌더 크롤 — 동일 섹션 ×3 중복 인입(B2 폴딩 246건 실측). top-k 잠식 위험
A19: 4호 | B19: 이용약관 시행일 2021-02-16 vs 크롤 2026-07 — 5년 격차, 약관 최신성 확인 요망
A21: ⑥ 추가(B4 승인분) — 영상 아티팩트 | B21: 차단: "Your browser does not support the video tag" / "브라우저가 video 태그를 지원하지 않습니다" / YouTube embed URL 단독 행 / [목록](…videoguide…) 복귀 링크. 존재 자체는 영상 의존 판정 신호로 사용
A22: ① 출제 경계(B4 승인분) | B22: 메타 사실 단위는 존재·위치형 질문만 성립. 방법 상세형 출제 금지(영상 의존) — 상세 부재는 E형 소재
A23: ① 판정 3분기(B4-1 사후 승인 반영) | B23: (1) 성립(메타): 존재 사실만 텍스트 성립 → 존재·위치형 출제만, 방법 상세 금지 / (2) 성립(대본 전문): 절차가 텍스트로 완결 실재 → 방법 상세 출제 허용, 화면 지시 표현부는 발췌 제외 / (3) 부분 성립(요약): 요약 수준 → 방법 상세 금지 / (+불성립: 텍스트 부재 → 사람확인)
A24: 5호 | B24: URL 정규화 누락 — ?p=ID ↔ pretty slug 동일 포스트 이중 인입. 실측: 영상가이드 64/64 + 사례 35/35 = 99문서 확정(blog 대조 후 최종), 중복 청크: 영상가이드분 467 + 사례분 별도 실측 예정, url_variants 전건 variant_count=1(변형 미접힘 증거). 검색 top-k 잠식·저장 낭비
A25: 정정 이력 | B25: B0 계리표 "영상가이드 64건 별개 콘텐츠" 판단 정정(2026-07-13) — 동일 포스트 URL 변형. B4 계획서 ④의 B4-2 예상 규모(65~100단위) 전제도 함께 무효(실제: 폴딩 64/신규 0). 레거시 규칙 ②는 B4-2 적용 대상 소멸, 규칙 자체는 존치(향후 배치 유효)

Sheet B0_계리
A1: 분류 | B1: 건수 | C1: 배치 배정 | D1: 비고
A2: 영상가이드 | B2: =COUNTIF(B0_분류표!D:D,A2) -> 64 | C2: B4 | D2: [정정 2026-07-13] 당초 "정식 67건과 제목 중복 0 — 별개 콘텐츠"로 보고했으나 내용 수준 재대조 결과 64/64 동일 포스트(URL 변형)로 확인. B4-2에서 문서 수준 폴딩 처리. 원인: CSV title 필드 대조 공전(내용 수준 대조 부재)
A3: 도입사례 | B3: =COUNTIF(B0_분류표!D:D,A3) -> 35 | C3: B5 | D3: Customer Success story / CASE STUDY 마커
A4: 블로그 | B4: =COUNTIF(B0_분류표!D:D,A4) -> 19 | C4: B6 | D4: 사이트 자체 태그 보유(인사이트12·소식4·기능2·활용팁1)
A5: 제품·기능 안내 | B5: =COUNTIF(B0_분류표!D:D,A5) -> 1 | C5: B2 | D5: 리모트뷰박스 랜딩 1건
A6: 구매·안내 페이지 | B6: =COUNTIF(B0_분류표!D:D,A6) -> 1 | C6: B2 | D6: 라이선스 구매 로그인 안내 1건
A7: 합계 | B7: =SUM(B2:B6) -> 120 | D7: 분류별 건수 합 = 120 (소실 0)

Sheet B0_분류표
A1: # | B1: doc_key | C1: canonical_url | D1: 분류 | E1: 분류 근거 | F1: 추출 제목 | G1: 게시일 | H1: 본문 자수(보일러플레이트 제거 후) | I1: 청크 수(실측) | J1: 배치 배정
A2: 1 | B2: eae37f69e968 | C2: https://content.rview.com/ko/?p=15295 | D2: 영상가이드 | E2: videoguide 관련콘텐츠 구조·무날짜 | F2: 10\. 원격으로 PC를 켜고 제어하기 | H2: 1993 | I2: 6 | J2: B4
A3: 2 | B3: 1f4ec3cab231 | C3: https://content.rview.com/ko/?p=15296 | D3: 영상가이드 | E3: videoguide 관련콘텐츠 구조·무날짜 | F3: 9\. RemoteView에서 WOL 등록확인 | H3: 1972 | I3: 6 | J3: B4
A4: 3 | B4: 75a315543d3e | C4: https://content.rview.com/ko/?p=15297 | D4: 영상가이드 | E4: videoguide 관련콘텐츠 구조·무날짜 | F4: 8\. 고정 IP 환경에서 RemoteView로 WOL 기기를 등록하는 방법 | H4: 1981 | I4: 6 | J4: B4
A5: 4 | B5: 45852ee51824 | C5: https://content.rview.com/ko/?p=15298 | D5: 영상가이드 | E5: videoguide 관련콘텐츠 구조·무날짜 | F5: 7\. 고정 IP 환경에서 WOL 설정 | H5: 1957 | I5: 6 | J5: B4
A6: 5 | B6: 6e25ca3ff5b2 | C6: https://content.rview.com/ko/?p=15299 | D6: 영상가이드 | E6: videoguide 관련콘텐츠 구조·무날짜 | F6: 6\. DHCP 환경에서 WOL 설정 | H6: 1996 | I6: 6 | J6: B4
A7: 6 | B7: 5ed31f27c762 | C7: https://content.rview.com/ko/?p=15300 | D7: 영상가이드 | E7: videoguide 관련콘텐츠 구조·무날짜 | F7: 5\. WOL 장비 및 MAC Address 확인 | H7: 1959 | I7: 6 | J7: B4
A8: 7 | B8: 2298df8e6ee8 | C8: https://content.rview.com/ko/?p=15301 | D8: 영상가이드 | E8: videoguide 관련콘텐츠 구조·무날짜 | F8: 4\. WOL 도입 전 테스트하기 | H8: 2001 | I8: 6 | J8: B4
A9: 8 | B9: 4843ba5b636a | C9: https://content.rview.com/ko/?p=15302 | D9: 영상가이드 | E9: videoguide 관련콘텐츠 구조·무날짜 | F9: 3\. WOL 기능 사용을 위한 BIOS(UEFI) 진입과 설정 | H9: 1970 | I9: 6 | J9: B4
A10: 9 | B10: 0e774a5ac260 | C10: https://content.rview.com/ko/?p=15303 | D10: 영상가이드 | E10: videoguide 관련콘텐츠 구조·무날짜 | F10: 2\. 윈도우 설정 방법 (WOL 체크) | H10: 1962 | I10: 6 | J10: B4
A11: 10 | B11: 068e4cf3778c | C11: https://content.rview.com/ko/?p=15304 | D11: 영상가이드 | E11: videoguide 관련콘텐츠 구조·무날짜 | F11: 1\. RemoteWOL 소개 | H11: 1952 | I11: 6 | J11: B4
A12: 11 | B12: a8cdc3a693d9 | C12: https://content.rview.com/ko/?p=15305 | D12: 영상가이드 | E12: videoguide 관련콘텐츠 구조·무날짜 | F12: 14\. Windows LogOn 사용하기 | H12: 2853 | I12: 7 | J12: B4
A13: 12 | B13: e9c7bd2ff6cc | C13: https://content.rview.com/ko/?p=15306 | D13: 영상가이드 | E13: videoguide 관련콘텐츠 구조·무날짜 | F13: 13\. Google OTP 사용하기 | H13: 2860 | I13: 7 | J13: B4
... A100: 99 | B100: 71315a714aa9 | C100: https://content.rview.com/ko/?p=25175 | D100: 도입사례 | E100: 제조 | F100: 고위험 현장 이동 120분 단축! 중공업 특수 장비 원격제어 사례 H사 | H100: 5184 | I100: 10 | J100: B5
A101: 100 | B101: a82bd97bf31b | C101: https://content.rview.com/ko/?p=15916 | D101: 블로그 | E101: 사이트 태그: 인사이트 (2022.07.25) | F101: 값비싼 데스크톱 가상화(VDI)? | G101: 2022.07.25 | H101: 5666 | I101: 11 | J101: B6
A102: 101 | B102: b4a45fe674f2 | C102: https://content.rview.com/ko/?p=17447 | D102: 블로그 | E102: 사이트 태그: 활용팁 (2023.10.17) | F102: 공공기관 외주 용역 관리의 숨은 조력자, 온라인 용역 통제 시스템 | G102: 2023.10.17 | H102: 13937 | I102: 26 | J102: B6
A103: 102 | B103: 282efa49c554 | C103: https://content.rview.com/ko/?p=18745 | D103: 블로그 | E103: 사이트 태그: 기능 (2024.06.14) | F103: \[기능 업데이트\] RS 어시스턴트 | G103: 2024.06.14 | H103: 2686 | I103: 7 | J103: B6
A104: 103 | B104: 6edadeb7f817 | C104: https://content.rview.com/ko/?p=19265 | D104: 블로그 | E104: 사이트 태그: 소식 (2024.11.06) | F104: \[이벤트\] ‘제 24회 공공솔루션마켓’ 행사 참가 안내 | G104: 2024.11.06 | H104: 6369 | I104: 14 | J104: B6
A105: 104 | B105: 0a18a0284d2a | C105: https://content.rview.com/ko/?p=19655 | D105: 블로그 | E105: 사이트 태그: 소식 (2025.02.24) | F105: 정보 보안 국제 표준 ISO/IEC 27001:2022 인증 취득! | G105: 2025.02.24 | H105: 7988 | I105: 16 | J105: B6
A106: 105 | B106: d982b98e20d1 | C106: https://content.rview.com/ko/?p=19735 | D106: 블로그 | E106: 사이트 태그: 소식 (2025.03.06) | F106: \[이벤트\] 알서포트, 제25회 공공솔루션마켓 참가 안내 | G106: 2025.03.06 | H106: 6178 | I106: 14 | J106: B6
A107: 106 | B107: 03f026a436d5 | C107: https://content.rview.com/ko/?p=19867 | D107: 블로그 | E107: 사이트 태그: 소식 (2025.03.27) | F107: AI로 진화한 OT 관리 솔루션 – 리모트뷰 | G107: 2025.03.27 | H107: 8039 | I107: 15 | J107: B6
A108: 107 | B108: d3581b53e37e | C108: https://content.rview.com/ko/?p=19899 | D108: 블로그 | E108: 사이트 태그: 인사이트 (2025.03.28) | F108: 이제는 상주 개발보다 효율적인 원격 개발 시대 | G108: 2025.03.28 | H108: 9264 | I108: 17 | J108: B6
A109: 108 | B109: bea46814a07b | C109: https://content.rview.com/ko/?p=20341 | D109: 블로그 | E109: 사이트 태그: 인사이트 (2025.05.12) | F109: No.1 키오스크 원격제어 서비스 짚어보기: | G109: 2025.05.12 | H109: 12640 | I109: 23 | J109: B6
A110: 109 | B110: 55b79b0f37f2 | C110: https://content.rview.com/ko/?p=20397 | D110: 블로그 | E110: 사이트 태그: 인사이트 (2025.05.16) | F110: \[제조업 랜섬웨어 비상!\] | G110: 2025.05.16 | H110: 13544 | I110: 24 | J110: B6
A111: 110 | B111: 0ba6f1ac53e3 | C111: https://content.rview.com/ko/?p=24689 | D111: 블로그 | E111: 사이트 태그: 인사이트 (2026.03.30) | F111: 설비 교체 없이 5분 만에? 노후 시설 공장 스마트팩토리 구현 전략 | G111: 2026.03.30 | H111: 12707 | I111: 23 | J111: B6
A112: 111 | B112: 2111acd6ec34 | C112: https://content.rview.com/ko/?p=24705 | D112: 블로그 | E112: 사이트 태그: 인사이트 (2026.03.25) | F112: 정부 재택근무 권고와 차량 5부제 의무화: 기업 필수 대응 가이드 | G112: 2026.03.25 | H112: 16949 | I112: 29 | J112: B6
... A119: 118 | B119: 5fafe59d7c38 | C119: https://content.rview.com/ko/?p=24849 | D119: 블로그 | E119: 사이트 태그: 기능 (2026.04.14) | F119: \[리모트뷰 8.5.0 업데이트\] 최대 60FPS로 끊김 없이 부드럽게! MS SSO 연동 & macOS 강화 | G119: 2026.04.14 | H119: 13329 | I119: 24 | J119: B6
A120: 119 | B120: ed3f92a006a7 | C120: https://content.rview.com/ko/?p=24107 | D120: 제품·기능 안내 | E120: 리모트뷰박스 제품 랜딩 (무날짜·기능 사양 서술) | F120: 현장 제어가 필요한 순간, | H120: 2078 | I120: 5 | J120: B2
A121: 120 | B121: 0a81e5359018 | C121: https://content.rview.com/ko/?p=13953 | D121: 구매·안내 페이지 | E121: 라이선스 구매 로그인 안내 (제목 헤딩 부재) | F121: 리모트뷰 라이선스 구매 안내 | H121: 1243 | I121: 5 | J121: B2

Sheet B1_커버리지맵
A1: # | B1: Unit ID | C1: type | D1: title | E1: description | F1: product | G1: feature | H1: user_type | I1: acl_level | J1: intent | K1: source/resource | L1: source_location | M1: related_units | N1: 이 단위가 말하는 사실 | O1: 답변 가능한 질문 | P1: tags | Q1: citation_id | R1: extracted_by | S1: confidence | T1: 상태 | U1: 비고
A2: 1 | B2: RV-MANUAL-ENT-001 | C2: Manual | D2: RemoteView Enterprise SaaS 사용자 가이드 | E2: 이중 로그인을 통한 보안 강화 | F2: RemoteView | G2: 이중 로그인을 통한 보안 강화 | H2: 관리자 | I2: 공개 | J2: 기능/가능 여부 확인 | K2: https://files.rsupport.com/ko/remoteview/guides/RemoteView_Enterprise_SaaS_User_Guide_kr.pdf | L2: chunk 19 / ● 이중 로그인을 통한 보안 강화 | N2: 서비스 이용 최소/권장 환경 리모트뷰에서 사용자는 사용자 페이지 또는 전용 PC 애플리케이션 콘솔을 이용해 원격지 PC를 관리할 수 있습니다. PC 환경은 다음과 같이 사용할 것을 권장합니다. <Windows> 운영체제 Windows 10 이상, Windows Server 2019 이상 ~ Windows 11 25H2 (Standard/Enterprise Edition 기준) CPU Pentium 4 2.0 GHz 메모리 512MB 이상 웹 브라우저 Chrome 100 이상/ Edge 97 이상 Whale 3.15.136.16 이상 / Firefox 96 이상 / Opera 83 이상 네트워크 Modem, ADSL, LAN, 공인 IP 또는 가상 IP 지원 (무선지원) 방화벽 Out Bound 80(http) / 443(https) Port Open *Windows 10 미만 버전(예: Windows 7, 8 등)에서도 제품이 실행될 수는 있으나, 보다 안정적인 사용을 위해 Windows 10 이상 환경에서의 사용을 권장 드립니다. <macOS> 운영체제 OS 13~OS 26 웹 브라우저 Chrome 100 이상 / Safari 16이상 Whale 3.16.138.21 이상 / Firefox 96 이상 /Opera 83 이상 네트워크 Modem, ADSL, LAN, 공인 IP 또는 가상 IP 지원 (무선지원) 방화벽 Out Bound 80(http) / 443(https) Port Open <Linux> (에이전트) 운영체제 Cent OS 7.0 (64bit), Redhat OS 7.0, 8.0(64bit) Ubuntu 18.04, 20.04, 22.04(64bit) Rocky Linux: 8.0 한컴OS Gooroom 2~3, TMax OS 21 웹 브라우저 Chrome 100 이상/ Firefox 96 이상 CPU 1GHz 이상 메모리 512MB 이상 네트워크 Fast Ethernet 방화벽 Out Bound 80(http) / 443(https) Port Open <Android> 뷰어 운영체제 Android 8.0 ~16.0 에이전트 운영체제 Android 8.0 ~16.0 <iOS> (전용 뷰어 앱) 운영체제 iOS 16.0 ~ 26.0 4. 리모트뷰 사용자 페이지 메인 페이지 리모트뷰 사용자 페이지는 모든 사용자가 접속하여 리모트뷰 기능을 사용할 수 있는 페이지입니다. 관리자는 리모트뷰 서비스에 관한 모든 사항을 확인/변경할 수 있습니다. 접속 URL: https://www.rview.com/ 로그인 전 로그인 후 (로그인 후 브라우저의 뒤로 가기 클릭 시, 로그인 정보가 노출되지 않을 경우 브라우저 새로고침 버튼을 클릭하면 로그인 정보 페이지가 노출됩니다.) | O2: RemoteView의 이중 로그인을 통한 보안 강화은(는) 무엇인가요? | P2: RemoteView, ENT, 이중 로그인을 통한 보안 강화 | Q2: RV-MANUAL-ENT-001 | R2: Claude(Fable5) | S2: 상 | T2: 미검토
A3: 2 | B3: RV-MANUAL-ENT-002 | C3: Manual | D3: RemoteView Enterprise SaaS 사용자 가이드 | E3: 메뉴 (LNB_Local Navigation Bar) > 원격지 PC 관리 | F3: RemoteView | G3: 원격지 PC 관리 | H3: 관리자 | I3: 공개 | J3: 기능/가능 여부 확인 | K3: https://files.rsupport.com/ko/remoteview/guides/RemoteView_Enterprise_SaaS_User_Guide_kr.pdf | L3: chunk 24 / §메뉴 (LNB_Local Navigation Bar) / ● 원격지 PC 관리 | N3: 리모트뷰 에이전트가 설치된 기기를 관리하고 원격 접속을 할 수 있는 페이지입니다. | O3: RemoteView의 원격지 PC 관리은(는) 무엇인가요? | P3: RemoteView, ENT, 원격지 PC 관리 | Q3: RV-MANUAL-ENT-002 | R3: Claude(Fable5) | S3: 중 | T3: 미검토
A4: 3 | B4: RV-MANUAL-ENT-003 | C4: Manual | D4: RemoteView Enterprise SaaS 사용자 가이드 | E4: 메뉴 (LNB_Local Navigation Bar) > 라이브뷰 | F4: RemoteView | G4: 라이브뷰 | H4: 관리자 | I4: 공개 | J4: 기능/가능 여부 확인 | K4: https://files.rsupport.com/ko/remoteview/guides/RemoteView_Enterprise_SaaS_User_Guide_kr.pdf | L4: chunk 24 / §메뉴 (LNB_Local Navigation Bar) / ● 라이브뷰 | N4: 등록된 기기를 모니터링 할 수 있는 페이지입니다. | O4: RemoteView의 라이브뷰은(는) 무엇인가요? | P4: RemoteView, ENT, 라이브뷰 | Q4: RV-MANUAL-ENT-003 | R4: Claude(Fable5) | S4: 중 | T4: 미검토
A5: 4 | B5: RV-MANUAL-ENT-004 | C5: Manual | D5: RemoteView Enterprise SaaS 사용자 가이드 | E5: 메뉴 (LNB_Local Navigation Bar) > 사용자 관리 | F5: RemoteView | G5: 사용자 관리 | H5: 관리자 | I5: 공개 | J5: 기능/가능 여부 확인 | K5: https://files.rsupport.com/ko/remoteview/guides/RemoteView_Enterprise_SaaS_User_Guide_kr.pdf | L5: chunk 24 / §메뉴 (LNB_Local Navigation Bar) / ● 사용자 관리 | N5: 등록된 모든 사용자에 대해 관리할 수 있는 페이지입니다. * 관리자, 매니저계정 권한에서만 제공됩니다. | O5: RemoteView의 사용자 관리은(는) 무엇인가요? | P5: RemoteView, ENT, 사용자 관리 | Q5: RV-MANUAL-ENT-004 | R5: Claude(Fable5) | S5: 중 | T5: 미검토
A6: 5 | B6: RV-MANUAL-ENT-005 | C6: Manual | D6: RemoteView Enterprise SaaS 사용자 가이드 | E6: 메뉴 (LNB_Local Navigation Bar) > 조직관리 | F6: RemoteView | G6: 조직관리 | H6: 관리자 | I6: 공개 | J6: 기능/가능 여부 확인 | K6: https://files.rsupport.com/ko/remoteview/guides/RemoteView_Enterprise_SaaS_User_Guide_kr.pdf | L6: chunk 24 / §메뉴 (LNB_Local Navigation Bar) / ● 조직관리 | N6: 사용자 그룹 추가를 통해 등록된 모든 사용자에 대해 관리할 수 있는 페이지입니다. * 관리자, 매니저계정 권한에서만 제공됩니다. | O6: RemoteView의 조직관리은(는) 무엇인가요? | P6: RemoteView, ENT, 조직관리 | Q6: RV-MANUAL-ENT-005 | R6: Claude(Fable5) | S6: 상 | T6: 미검토
A7: 6 | B7: RV-MANUAL-ENT-006 | C7: Manual | D7: RemoteView Enterprise SaaS 사용자 가이드 | E7: 메뉴 (LNB_Local Navigation Bar) > 사용통계 | F7: RemoteView | G7: 사용통계 | H7: 관리자 | I7: 공개 | J7: 기능/가능 여부 확인 | K7: https://files.rsupport.com/ko/remoteview/guides/RemoteView_Enterprise_SaaS_User_Guide_kr.pdf | L7: chunk 24 / §메뉴 (LNB_Local Navigation Bar) / ● 사용통계 | N7: 원격접속 및 제어 이력과 통계가 차트 및 기록으로 제공되는 페이지입니다. | O7: RemoteView의 사용통계은(는) 무엇인가요? | P7: RemoteView, ENT, 사용통계 | Q7: RV-MANUAL-ENT-006 | R7: Claude(Fable5) | S7: 중 | T7: 미검토
A8: 7 | B8: RV-MANUAL-ENT-007 | C8: Manual | D8: RemoteView Enterprise SaaS 사용자 가이드 | E8: 메뉴 (LNB_Local Navigation Bar) > 환경설정 | F8: RemoteView | G8: 환경설정 | H8: 관리자 | I8: 공개 | J8: 기능/가능 여부 확인 | K8: https://files.rsupport.com/ko/remoteview/guides/RemoteView_Enterprise_SaaS_User_Guide_kr.pdf | L8: chunk 24 / §메뉴 (LNB_Local Navigation Bar) / ● 환경설정 | N8: 계정 정보관리, 옵션 설정, 라이선스 구매 및 관리, 매뉴얼과 콘솔 애플리케이션을 다운로드할 수 있는 페이지입니다. | O8: RemoteView의 환경설정은(는) 무엇인가요? | P8: RemoteView, ENT, 환경설정 | Q8: RV-MANUAL-ENT-007 | R8: Claude(Fable5) | S8: 상 | T8: 미검토
A9: 8 | B9: RV-MANUAL-ENT-008 | C9: Manual | D9: RemoteView Enterprise SaaS 사용자 가이드 | E9: 메뉴 (LNB_Local Navigation Bar) > Simple Launcher 설치 | F9: RemoteView | G9: Simple Launcher 설치 | H9: 관리자 | I9: 공개 | J9: 설정/사용 방법 문의 | K9: https://files.rsupport.com/ko/remoteview/guides/RemoteView_Enterprise_SaaS_User_Guide_kr.pdf | L9: chunk 24 / §메뉴 (LNB_Local Navigation Bar) / ● Simple Launcher 설치 | N9: 웹 브라우저에 접속하여 로그인 후 원격제어를 하기 전에 자동으로 Simple Launcher가 설치됩니다. ① 아래 이미지와 같이 Simple Launcher를 설치할 exe파일을 실행합니다. (Simple Launcher 설치 안내 팝업) ② 다운로드 파일을 실행하여, 컴퓨터에 설치를 진행합니다. ③ 웹 브라우저에 Launcher 설치 안내 팝업의 [닫기] 버튼을 클릭하여, 창을 닫고 원격제어 서비스를 이용합니다. | O9: RemoteView에서 Simple Launcher 설치은(는) 어떻게 하나요? | P9: RemoteView, ENT, Simple Launcher 설치 | Q9: RV-MANUAL-ENT-008 | R9: Claude(Fable5) | S9: 상 | T9: 미검토
A10: 9 | B10: RV-MANUAL-ENT-009 | C10: Manual | D10: RemoteView Enterprise SaaS 사용자 가이드 | E10: 메뉴 (LNB_Local Navigation Bar) > Simple Launcher 수동 설치하기 | F10: RemoteView | G10: Simple Launcher 수동 설치하기 | H10: 관리자 | I10: 공개 | J10: 기능/가능 여부 확인 | K10: https://files.rsupport.com/ko/remoteview/guides/RemoteView_Enterprise_SaaS_User_Guide_kr.pdf | L10: chunk 24 / §메뉴 (LNB_Local Navigation Bar) / ● Simple Launcher 수동 설치하기 | N10: 원격제어가 정상적으로 실행되지 않을 경우, Launcher 파일을 수동으로 설치하여 문제를 해결하도록 합니다. 화면 상단의 [Simple Launcher 설치] 메뉴를 클릭하여, 파일을 수동으로 다운로드 받아 설치합니다. (Simple Launcher 설치 메뉴) | O10: RemoteView의 Simple Launcher 수동 설치하기은(는) 무엇인가요? | P10: RemoteView, ENT, Simple Launcher 수동 설 | Q10: RV-MANUAL-ENT-009 | R10: Claude(Fable5) | S10: 상 | T10: 미검토
A11: 10 | B11: RV-MANUAL-ENT-010 | C11: Manual | D11: RemoteView Enterprise SaaS 사용자 가이드 | E11: 메뉴 (LNB_Local Navigation Bar) > Simple Launcher 삭제하기 | F11: RemoteView | G11: Simple Launcher 삭제하기 | H11: 관리자 | I11: 공개 | J11: 설정/사용 방법 문의 | K11: https://files.rsupport.com/ko/remoteview/guides/RemoteView_Enterprise_SaaS_User_Guide_kr.pdf | L11: chunk 24 / §메뉴 (LNB_Local Navigation Bar) / ● Simple Launcher 삭제하기 | N11: ① 시작>제어판>프로그램>프로그램 추가/삭제 or 프로그램 및 기능을 엽니다. ② 프로그램 목록에서 ‘RemoteView Simple Launcher’를 선택합니다. ③ [제거]를 클릭합니다. ④ 삭제 프로세스가 동작합니다. | O11: RemoteView에서 Simple Launcher 삭제하기은(는) 어떻게 하나요? | P11: RemoteView, ENT, Simple Launcher 삭제하기 | Q11: RV-MANUAL-ENT-010 | R11: Claude(Fable5) | S11: 상 | T11: 미검토
A12: 11 | B12: RV-MANUAL-ENT-011 | C12: Manual | D12: RemoteView Enterprise SaaS 사용자 가이드 | E12: 원격지 PC 탐색기 > 즐겨찾기 | F12: RemoteView | G12: 즐겨찾기 | H12: 관리자 | I12: 공개 | J12: 설정 방법 문의 | K12: https://files.rsupport.com/ko/remoteview/guides/RemoteView_Enterprise_SaaS_User_Guide_kr.pdf | L12: chunk 26 / §원격지 PC 탐색기 / ● 즐겨찾기 | N12: 사용자가 주로 사용하는 에이전트에 대해 카테고리를 생성해 사용할 수 있으며 우 클릭 시 제공되는 Context Menu로 보다 쉽게 관리할 수 있습니다. ⮚ 최대 5개 카테고리 생성이 가능하며, 카테고리명은 최소 1글자 이상으로 설정할 수 있습니다. ⮚ 카테고리 명 우측 숫자 표시는 on 상태 PC 와 그룹의 전체 PC의 수를 의미합니다. | O12: RemoteView의 즐겨찾기은(는) 무엇인가요? | P12: RemoteView, ENT, 즐겨찾기 | Q12: RV-MANUAL-ENT-011 | R12: Claude(Fable5) | S12: 상 | T12: 미검토
A13: 12 | B13: RV-MANUAL-ENT-012 | C13: Manual | D13: RemoteView Enterprise SaaS 사용자 가이드 | E13: 원격지 PC 탐색기 > 원격지 PC 리스트 | F13: RemoteView | G13: 원격지 PC 리스트 | H13: 관리자 | I13: 공개 | J13: 기능/가능 여부 확인 | K13: https://files.rsupport.com/ko/remoteview/guides/RemoteView_Enterprise_SaaS_User_Guide_kr.pdf | L13: chunk 26 / §원격지 PC 탐색기 / ● 원격지 PC 리스트 | N13: 대표 아이디에 등록된 모든 그룹과 PC 목록을 트리 구조의 형태로 볼 수 있으며 우 클릭 시 제공되는 Context Menu로 대표, 그룹, PC를 보다 쉽게 관리 및 원격제어 기능을 사용할 수 있습니다. ⮚ 환경설정 or 라이선스 상품에 따라 사용할 수 있는 기능의 차이가 있습니다 ⮚ 그룹 명 우측 숫자 표시는 on 상태 PC 와 그룹의 전체 PC의 수를 의미합니다. | O13: RemoteView의 원격지 PC 리스트은(는) 무엇인가요? | P13: RemoteView, ENT, 원격지 PC 리스트 | Q13: RV-MANUAL-ENT-012 | R13: Claude(Fable5) | S13: 상 | T13: 미검토
... A29: 28 | B29: RV-MANUAL-ENT-028 | C29: Manual | D29: RemoteView Enterprise SaaS 사용자 가이드 | E29: 사용자별 제어 권한 > 보기 | F29: RemoteView | G29: 보기 | H29: 관리자 | I29: 공개 | J29: 설정/사용 방법 문의 | K29: https://files.rsupport.com/ko/remoteview/guides/RemoteView_Enterprise_SaaS_User_Guide_kr.pdf | L29: chunk 34 / §사용자별 제어 권한 / ● 보기 | N29: ① [아이콘으로 표시], [목록으로 표시]을 클릭합니다. ② Contents 영역의 페이지 정렬이 아이콘 정렬, 리스트 정렬로 전환됩니다. | O29: RemoteView에서 보기은(는) 어떻게 하나요? | P29: RemoteView, ENT, 보기 | Q29: RV-MANUAL-ENT-028 | R29: Claude(Fable5) | S29: 상 | T29: 미검토
A30: 29 | B30: RV-MANUAL-ENT-029 | C30: Manual | D30: RemoteView Enterprise SaaS 사용자 가이드 | E30: 사용자별 제어 권한 > 소팅 | F30: RemoteView | G30: 소팅 | H30: 관리자 | I30: 공개 | J30: 기능/가능 여부 확인 | K30: https://files.rsupport.com/ko/remoteview/guides/RemoteView_Enterprise_SaaS_User_Guide_kr.pdf | L30: chunk 34 / §사용자별 제어 권한 / ● 소팅 | N30: 선택한 옵션값대로 목록이 소팅 됩니다. | O30: RemoteView의 소팅은(는) 무엇인가요? | P30: RemoteView, ENT, 소팅 | Q30: RV-MANUAL-ENT-029 | R30: Claude(Fable5) | S30: 하 | T30: 근거약함 | U30: 본문 25자 미만 — 원문 근거 짧음
A31: 30 | B31: RV-MANUAL-ENT-030 | C31: Manual | D31: RemoteView Enterprise SaaS 사용자 가이드 | E31: 사용자별 제어 권한 > 검색 | F31: RemoteView | G31: 검색 | H31: 관리자 | I31: 공개 | J31: 기능/가능 여부 확인 | K31: https://files.rsupport.com/ko/remoteview/guides/RemoteView_Enterprise_SaaS_User_Guide_kr.pdf | L31: chunk 34 / §사용자별 제어 권한 / ● 검색 | N31: 입력한 검색어와 일치하는 데이터가 검색됩니다. 라이브뷰 | O31: RemoteView의 검색은(는) 무엇인가요? | P31: RemoteView, ENT, 검색 | Q31: RV-MANUAL-ENT-030 | R31: Claude(Fable5) | S31: 중 | T31: 미검토
A32: 31 | B32: RV-MANUAL-ENT-031 | C32: Manual | D32: RemoteView Enterprise SaaS 사용자 가이드 | E32: 사용자별 제어 권한 > 새로고침 | F32: RemoteView | G32: 새로고침 | H32: 관리자 | I32: 공개 | J32: 설정/사용 방법 문의 | K32: https://files.rsupport.com/ko/remoteview/guides/RemoteView_Enterprise_SaaS_User_Guide_kr.pdf | L32: chunk 34 / §사용자별 제어 권한 / ● 새로고침 | N32: ① [새로고침] 아이콘을 클릭합니다. ② 웹 페이지 화면의 데이터가 갱신됩니다. | O32: RemoteView에서 새로고침은(는) 어떻게 하나요? | P32: RemoteView, ENT, 새로고침 | Q32: RV-MANUAL-ENT-031 | R32: Claude(Fable5) | S32: 중 | T32: 미검토
A33: 32 | B33: RV-MANUAL-ENT-032 | C33: Manual | D33: RemoteView Enterprise SaaS 사용자 가이드 | E33: 사용자별 제어 권한 > 즐겨찾기 | F33: RemoteView | G33: 즐겨찾기 | H33: 관리자 | I33: 공개 | J33: 설정/사용 방법 문의 | K33: https://files.rsupport.com/ko/remoteview/guides/RemoteView_Enterprise_SaaS_User_Guide_kr.pdf | L33: chunk 34 / §사용자별 제어 권한 / ● 즐겨찾기 | N33: ① [즐겨찾기 추가] 아이콘을 클릭합니다. <접근방법> 1 툴바 > [즐겨찾기 추가] 버튼 클릭 2 원격지PC탐색기 -> PC 마우스 오른쪽 버튼 클릭 -> ‘즐겨찾기’ 클릭 3 Contents 영역 -> PC 마우스 오른쪽 버튼 클릭 -> ‘즐겨찾기’ 클릭 ② 카테고리를 선택합니다. ③ [적용] or [취소] 버튼을 클릭합니다. ④ [적용] : 선택한 카테고리에 PC 추가 ✔ [적용] : 선택한 카테고리에 PC 추가 ✔ [취소] : 취소 | O33: RemoteView에서 즐겨찾기은(는) 어떻게 하나요? | P33: RemoteView, ENT, 즐겨찾기 | Q33: RV-MANUAL-ENT-032 | R33: Claude(Fable5) | S33: 상 | T33: 미검토
A34: 33 | B34: RV-MANUAL-ENT-033 | C34: Manual | D34: RemoteView Enterprise SaaS 사용자 가이드 | E34: 사용자별 제어 권한 > 이동 | F34: RemoteView | G34: 이동 | H34: 관리자 | I34: 공개 | J34: 설정/사용 방법 문의 | K34: https://files.rsupport.com/ko/remoteview/guides/RemoteView_Enterprise_SaaS_User_Guide_kr.pdf | L34: chunk 35 / §사용자별 제어 권한 / ● 이동 | N34: ① [이동] 아이콘을 클릭합니다. <접근방법> 즐겨찾기 그룹 선택 -> PC 선택 -> 툴바 [이동] 버튼 클릭 ② 에이전트 그룹 이동 팝업이 노출됩니다. ③ 이동할 그룹을 선택합니다. ④ [적용] or [취소] 버튼을 클릭합니다. ✔ [적용] : 선택한 그룹으로 PC 이동 ✔ [취소] : 취소 | O34: RemoteView에서 이동은(는) 어떻게 하나요? | P34: RemoteView, ENT, 이동 | Q34: RV-MANUAL-ENT-033 | R34: Claude(Fable5) | S34: 상 | T34: 미검토
A35: 34 | B35: RV-MANUAL-ENT-034 | C35: Manual | D35: RemoteView Enterprise SaaS 사용자 가이드 | E35: 사용자별 제어 권한 > 삭제 | F35: RemoteView | G35: 삭제 | H35: 관리자 | I35: 공개 | J35: 설정/사용 방법 문의 | K35: https://files.rsupport.com/ko/remoteview/guides/RemoteView_Enterprise_SaaS_User_Guide_kr.pdf | L35: chunk 35 / §사용자별 제어 권한 / ● 삭제 | N35: ① [삭제] 아이콘을 클릭합니다. <접근방법> 1 즐겨찾기 그룹 선택 -> PC 선택 -> 툴바 [삭제] 버튼 클릭 2 즐겨찾기 그룹 선택 -> PC 마우스 오른쪽 버튼 클릭 -> ‘삭제’ 클릭 ② “삭제하시겠습니까?” 메시지창이 팝업 됩니다. ⮚ 보안확인 설정 시 보안확인창 팝업이 노출됩니다. ③ [적용] or [취소] 버튼을 클릭합니다. ✔ [적용] : 선택한 그룹 or PC 삭제 ✔ [취소] : 취소 | O35: RemoteView에서 삭제은(는) 어떻게 하나요? | P35: RemoteView, ENT, 삭제 | Q35: RV-MANUAL-ENT-034 | R35: Claude(Fable5) | S35: 상 | T35: 미검토
A36: 35 | B36: RV-MANUAL-ENT-035 | C36: Manual | D36: RemoteView Enterprise SaaS 사용자 가이드 | E36: 사용자별 제어 권한 > 크게보기 | F36: RemoteView | G36: 크게보기 | H36: 관리자 | I36: 공개 | J36: 설정/사용 방법 문의 | K36: https://files.rsupport.com/ko/remoteview/guides/RemoteView_Enterprise_SaaS_User_Guide_kr.pdf | L36: chunk 35 / §사용자별 제어 권한 / ● 크게보기 | N36: ① [크게보기] 아이콘을 클릭합니다. <접근방법> 1 ON 상태 PC 선택 -> 툴바 [크게보기] 버튼 클릭 2 원격지 PC 탐색기 영역 -> ON 상태 PC마우스 오른쪽 버튼 클릭 -> ‘크게보기’ 또는 ‘재생’ 클릭 3 Contents 영역 -> ON 상태 PC 마우스 오른쪽 버튼 클릭 -> ‘크게보기’ 또는 ‘재생’ 클릭 ② 라이브뷰 팝업이 노출됩니다. ③ 원격지 PC 화면이 라이브뷰 팝업으로 보여 집니다. | O36: RemoteView에서 크게보기은(는) 어떻게 하나요? | P36: RemoteView, ENT, 크게보기 | Q36: RV-MANUAL-ENT-035 | R36: Claude(Fable5) | S36: 상 | T36: 미검토
A37: 36 | B37: RV-MANUAL-ENT-036 | C37: Manual | D37: RemoteView Enterprise SaaS 사용자 가이드 | E37: 사용자별 제어 권한 > 등록정보 | F37: RemoteView | G37: 등록정보 | H37: 관리자 | I37: 공개 | J37: 설정/사용 방법 문의 | K37: https://files.rsupport.com/ko/remoteview/guides/RemoteView_Enterprise_SaaS_User_Guide_kr.pdf | L37: chunk 35 / §사용자별 제어 권한 / ● 등록정보 | N37: ① [등록정보] 아이콘을 클릭합니다. <접근방법> 1 툴바 > [등록정보] 버튼 클릭 2 그룹, PC 마우스 오른쪽 버튼 클릭 -> ‘등록정보’’ 클릭 ② 그룹 or PC 등록정보 팝업이 노출됩니다. ③ 데이터를 변경합니다. ④ [적용] or [취소] 버튼을 클릭합니다. ✔ [적용] : 변경된 데이터로 등록정보가 변경됩니다. ✔ [취소] : 기존 데이터가 유지됩니다. | O37: RemoteView에서 등록정보은(는) 어떻게 하나요? | P37: RemoteView, ENT, 등록정보 | Q37: RV-MANUAL-ENT-036 | R37: Claude(Fable5) | S37: 상 | T37: 미검토
A38: 37 | B38: RV-MANUAL-ENT-037 | C38: Manual | D38: RemoteView Enterprise SaaS 사용자 가이드 | E38: 사용자별 제어 권한 > 슬라이더 | F38: RemoteView | G38: 슬라이더 | H38: 관리자 | I38: 공개 | J38: 설정/사용 방법 문의 | K38: https://files.rsupport.com/ko/remoteview/guides/RemoteView_Enterprise_SaaS_User_Guide_kr.pdf | L38: chunk 35 / §사용자별 제어 권한 / ● 슬라이더 | N38: ① 슬라이더 Bar에 마우스 클릭을 합니다. ② Bar를 좌, 우로 이동합니다. ③ Contents 영역의 화면 아이콘 크기가 축소되거나, 확대됩니다. 화면의 아이콘 크기가 조절됩니다. | O38: RemoteView에서 슬라이더은(는) 어떻게 하나요? | P38: RemoteView, ENT, 슬라이더 | Q38: RV-MANUAL-ENT-037 | R38: Claude(Fable5) | S38: 상 | T38: 미검토
A39: 38 | B39: RV-MANUAL-ENT-038 | C39: Manual | D39: RemoteView Enterprise SaaS 사용자 가이드 | E39: 사용자별 제어 권한 > 소팅 | F39: RemoteView | G39: 소팅 | H39: 관리자 | I39: 공개 | J39: 기능/가능 여부 확인 | K39: https://files.rsupport.com/ko/remoteview/guides/RemoteView_Enterprise_SaaS_User_Guide_kr.pdf | L39: chunk 36 / §사용자별 제어 권한 / ● 소팅 | N39: 선택한 옵션값 대로 목록이 소팅 됩니다. | O39: RemoteView의 소팅은(는) 무엇인가요? | P39: RemoteView, ENT, 소팅 | Q39: RV-MANUAL-ENT-038 | R39: Claude(Fable5) | S39: 하 | T39: 근거약함 | U39: 본문 25자 미만 — 원문 근거 짧음
A40: 39 | B40: RV-MANUAL-ENT-039 | C40: Manual | D40: RemoteView Enterprise SaaS 사용자 가이드 | E40: 사용자별 제어 권한 > 검색 | F40: RemoteView | G40: 검색 | H40: 관리자 | I40: 공개 | J40: 기능/가능 여부 확인 | K40: https://files.rsupport.com/ko/remoteview/guides/RemoteView_Enterprise_SaaS_User_Guide_kr.pdf | L40: chunk 36 / §사용자별 제어 권한 / ● 검색 | N40: 입력한 검색어와 일치하는 데이터가 검색됩니다. | O40: RemoteView의 검색은(는) 무엇인가요? | P40: RemoteView, ENT, 검색 | Q40: RV-MANUAL-ENT-039 | R40: Claude(Fable5) | S40: 중 | T40: 미검토
A41: 40 | B41: RV-MANUAL-ENT-040 | C41: Manual | D41: RemoteView Enterprise SaaS 사용자 가이드 | E41: 사용자/조직관리 > 원격지 PC > 새로고침 | F41: RemoteView | G41: 새로고침 | H41: 관리자 | I41: 공개 | J41: 설정/사용 방법 문의 | K41: https://files.rsupport.com/ko/remoteview/guides/RemoteView_Enterprise_SaaS_User_Guide_kr.pdf | L41: chunk 36 / §사용자/조직관리 > 원격지 PC / ● 새로고침 | N41: ① [새로고침] 아이콘을 클릭합니다. ② 웹 페이지 화면의 데이터가 갱신됩니다. | O41: RemoteView에서 새로고침은(는) 어떻게 하나요? | P41: RemoteView, ENT, 새로고침 | Q41: RV-MANUAL-ENT-040 | R41: Claude(Fable5) | S41: 중 | T41: 미검토
A42: 41 | B42: RV-MANUAL-ENT-041 | C42: Manual | D42: RemoteView Enterprise SaaS 사용자 가이드 | E42: 사용자/조직관리 > 원격지 PC > 매니저 추가 | F42: RemoteView | G42: 매니저 추가 | H42: 관리자 | I42: 공개 | J42: 설정/사용 방법 문의 | K42: https://files.rsupport.com/ko/remoteview/guides/RemoteView_Enterprise_SaaS_User_Guide_kr.pdf | L42: chunk 36 / §사용자/조직관리 > 원격지 PC / ● 매니저 추가 | N42: ① [매니저 추가] 아이콘을 클릭합니다. <접근방법> 1 툴바 > [매니저 추가] 버튼 클릭 2 마우스 오른쪽 버튼 클릭 -> ‘매니저 추가’ 클릭 3 하단 상세정보 -> 추가기능 -> ‘매니저 추가’ 클릭 ② 사용자 정보를 입력합니다. ③ [적용] or [취소] 버튼을 클릭합니다. ✔ [적용] : 새로운 매니저가 추가됩니다. ✔ [취소] : 취소 | O42: RemoteView에서 매니저 추가은(는) 어떻게 하나요? | P42: RemoteView, ENT, 매니저 추가 | Q42: RV-MANUAL-ENT-041 | R42: Claude(Fable5) | S42: 상 | T42: 미검토
A43: 42 | B43: RV-MANUAL-ENT-042 | C43: Manual | D43: RemoteView Enterprise SaaS 사용자 가이드 | E43: 사용자/조직관리 > 원격지 PC > 사용자 추가 | F43: RemoteView | G43: 사용자 추가 | H43: 관리자 | I43: 공개 | J43: 설정/사용 방법 문의 | K43: https://files.rsupport.com/ko/remoteview/guides/RemoteView_Enterprise_SaaS_User_Guide_kr.pdf | L43: chunk 36 / §사용자/조직관리 > 원격지 PC / ● 사용자 추가 | N43: ① [사용자 추가] 아이콘을 클릭합니다. <접근방법> 1 툴바 > [사용자 추가] 버튼 클릭 2 마우스 오른쪽 버튼 클릭 -> ‘사용자 추가’ 클릭 3 하단 상세정보 -> 추가기능 -> ‘사용자 추가’ 클릭 ② 사용자 정보를 입력합니다. ③ [적용] or [취소] 버튼을 클릭합니다. ✔ [적용] : 새로운 사용자가 추가됩니다. ✔ [취소] : 취소 | O43: RemoteView에서 사용자 추가은(는) 어떻게 하나요? | P43: RemoteView, ENT, 사용자 추가 | Q43: RV-MANUAL-ENT-042 | R43: Claude(Fable5) | S43: 상 | T43: 미검토
A44: 43 | B44: RV-MANUAL-ENT-043 | C44: Manual | D44: RemoteView Enterprise SaaS 사용자 가이드 | E44: 사용자/조직관리 > 원격지 PC > 즐겨찾기 | F44: RemoteView | G44: 즐겨찾기 | H44: 관리자 | I44: 공개 | J44: 설정/사용 방법 문의 | K44: https://files.rsupport.com/ko/remoteview/guides/RemoteView_Enterprise_SaaS_User_Guide_kr.pdf | L44: chunk 37 / §사용자/조직관리 > 원격지 PC / ● 즐겨찾기 | N44: ① [즐겨찾기] 아이콘을 클릭합니다. <접근방법> 1 툴바 > [즐겨찾기] 버튼 클릭 2 마우스 오른쪽 버튼 클릭 -> ‘즐겨찾기’ 클릭 3 하단 상세정보 -> 추가기능 -> ‘즐겨찾기’ 클릭 ② 카테고리를 선택합니다. ③ [적용] or [취소] 버튼을 클릭합니다. ✔ [적용] : 선택한 카테고리에 사용자 추가 ✔ [취소] : 취소 | O44: RemoteView에서 즐겨찾기은(는) 어떻게 하나요? | P44: RemoteView, ENT, 즐겨찾기 | Q44: RV-MANUAL-ENT-043 | R44: Claude(Fable5) | S44: 상 | T44: 미검토
A45: 44 | B45: RV-MANUAL-ENT-044 | C45: Manual | D45: RemoteView Enterprise SaaS 사용자 가이드 | E45: 사용자/조직관리 > 원격지 PC > 사용자 권한 할당 | F45: RemoteView | G45: 사용자 권한 할당 | H45: 관리자 | I45: 공개 | J45: 설정/사용 방법 문의 | K45: https://files.rsupport.com/ko/remoteview/guides/RemoteView_Enterprise_SaaS_User_Guide_kr.pdf | L45: chunk 37 / §사용자/조직관리 > 원격지 PC / ● 사용자 권한 할당 | N45: ① [사용자 권한 할당] 아이콘을 클릭합니다. <접근방법> 1 툴바 > [사용자 권한 할당] 버튼 클릭 2 사용자 마우스 오른쪽 버튼 클릭 -> ‘권한 할당’ 클릭 3 하단 상세정보 -> 추가기능 -> ‘권한 할당’ 클릭 ② 사용자 권한 할당 팝업이 노출됩니다. ③ 그룹, 에이전트를 선택합니다. ④ [적용] or [취소] 버튼을 클릭합니다. ✔ [적용] : 선택한 그룹, 에이전트에 사용자 할당 ✔ [취소] : 취소 참고: 상단 체크박스 선택/해제 시, 하단 사용자제어권한 열의 체크박스가 모두 일괄 선택/해제됩니다. 사용자 권한 이 [할당불가]인 경우, 권한 제어가 비활성 되어 있으므로 일괄선택/일괄해제가 불가능하고 [할당가능], [변경가능] 상태만 일괄선택/일괄해제 가능합니다. | O45: RemoteView에서 사용자 권한 할당은(는) 어떻게 하나요? | P45: RemoteView, ENT, 사용자 권한 할당 | Q45: RV-MANUAL-ENT-044 | R45: Claude(Fable5) | S45: 상 | T45: 미검토
A46: 45 | B46: RV-MANUAL-ENT-045 | C46: Manual | D46: RemoteView Enterprise SaaS 사용자 가이드 | E46: 사용자/조직관리 > 원격지 PC > 이동(즐겨찾기) | F46: RemoteView | G46: 이동(즐겨찾기) | H46: 관리자 | I46: 공개 | J46: 설정/사용 방법 문의 | K46: https://files.rsupport.com/ko/remoteview/guides/RemoteView_Enterprise_SaaS_User_Guide_kr.pdf | L46: chunk 37 / §사용자/조직관리 > 원격지 PC / ● 이동(즐겨찾기) | N46: ① [이동] 아이콘을 클릭합니다. <접근방법> 툴바 > [이동] 버튼 클릭 ② 즐겨찾기 이동 팝업 됩니다. ③ 이동할 그룹을 선택합니다. ④ [적용] or [취소] 버튼을 클릭합니다. ✔ [적용] : 선택한 즐겨찾기 카테고리에 사용자 추가 ✔ [취소] : 취소 | O46: RemoteView에서 이동(즐겨찾기)은(는) 어떻게 하나요? | P46: RemoteView, ENT, 이동(즐겨찾기) | Q46: RV-MANUAL-ENT-045 | R46: Claude(Fable5) | S46: 상 | T46: 미검토
A47: 46 | B47: RV-MANUAL-ENT-046 | C47: Manual | D47: RemoteView Enterprise SaaS 사용자 가이드 | E47: 사용자/조직관리 > 원격지 PC > 삭제 | F47: RemoteView | G47: 삭제 | H47: 관리자 | I47: 공개 | J47: 설정/사용 방법 문의 | K47: https://files.rsupport.com/ko/remoteview/guides/RemoteView_Enterprise_SaaS_User_Guide_kr.pdf | L47: chunk 38 / §사용자/조직관리 > 원격지 PC / ● 삭제 | N47: ① [삭제] 아이콘을 클릭합니다. <접근방법> 1 툴바 > [삭제] 버튼 클릭 2 마우스 오른쪽 버튼 클릭 -> ‘삭제’ 클릭 3 하단 상세정보 -> 추가기능 -> ‘삭제’ 클릭 ② “삭제하시겠습니까?” 메시지창이 팝업이 노출됩니다. ⮚ 보안확인 설정 시 보안 확인 창 팝업이 노출됩니다. ③ [적용] or [취소] 버튼을 클릭합니다. ✔ [적용] : 선택한 사용자 삭제 ✔ [취소] : 취소 | O47: RemoteView에서 삭제은(는) 어떻게 하나요? | P47: RemoteView, ENT, 삭제 | Q47: RV-MANUAL-ENT-046 | R47: Claude(Fable5) | S47: 상 | T47: 미검토
A48: 47 | B48: RV-MANUAL-ENT-047 | C48: Manual | D48: RemoteView Enterprise SaaS 사용자 가이드 | E48: 사용자/조직관리 > 원격지 PC > 등록정보 | F48: RemoteView | G48: 등록정보 | H48: 관리자 | I48: 공개 | J48: 설정/사용 방법 문의 | K48: https://files.rsupport.com/ko/remoteview/guides/RemoteView_Enterprise_SaaS_User_Guide_kr.pdf | L48: chunk 38 / §사용자/조직관리 > 원격지 PC / ● 등록정보 | N48: ① [등록정보] 아이콘을 클릭합니다. <접근방법> 1 툴바 > [등록정보] 버튼 클릭 2 마우스 오른쪽 버튼 클릭 -> ‘등록정보’ 클릭 3 하단 상세정보 -> 추가기능 -> ‘등록정보’ 클릭 ② 사용자 등록정보 팝업이 노출됩니다. 이메일 항목은 이메일 등록 여부 및 인증 상태에 따라 미등록, 미인증, 인증완료로 표시됩니다. - 미등록 : 이메일이 등록되지 않은 상태 - 미인증 : 이메일이 등록되어 있으나 인증 절차를 완료하지 않은 상태 - 인증완료 : 등록된 이메일로 인증 완료된 상태 대표 옵션 설정에서 이메일 보안 강화 설정에 따라 이메일 미등록이나 미인증 상태에서는 로그인, 에이전트 연결 등이 제한될 수 있습니다. ③ 데이터를 변경합니다. ④ 사용자/매니저 계정에 ‘에이전트 설치 허용’옵션 적용하여 에이전트 등록 권한과 설치 허용 대수(제한없음 또는 1~5대)를 설정할 수 있습니다. ⑤ [적용] or [취소] 버튼을 클릭합니다. ✔ [적용] : 사용자 등록정보 변경 ✔ [취소] : 기존 데이터가 유지 | O48: RemoteView에서 등록정보은(는) 어떻게 하나요? | P48: RemoteView, ENT, 등록정보 | Q48: RV-MANUAL-ENT-047 | R48: Claude(Fable5) | S48: 상 | T48: 미검토
A49: 48 | B49: RV-MANUAL-ENT-048 | C49: Manual | D49: RemoteView Enterprise SaaS 사용자 가이드 | E49: 사용자 별 에이전트 설치 수 제한 기능 > 엑셀 파일로 내보내기 | F49: RemoteView | G49: 엑셀 파일로 내보내기 | H49: 관리자 | I49: 공개 | J49: 설정/사용 방법 문의 | K49: https://files.rsupport.com/ko/remoteview/guides/RemoteView_Enterprise_SaaS_User_Guide_kr.pdf | L49: chunk 39 / §사용자 별 에이전트 설치 수 제한 기능 / ● 엑셀 파일로 내보내기 | N49: ① [엑셀 파일로 내보내기] 아이콘을 클릭합니다. <접근방법> 툴바 > [엑셀 파일로 내보내기] 버튼 클릭 ✔ [저장] : user-list.xlsx 파일이 PC에 저장됩니다. | O49: RemoteView에서 엑셀 파일로 내보내기은(는) 어떻게 하나요? | P49: RemoteView, ENT, 엑셀 파일로 내보내기 | Q49: RV-MANUAL-ENT-048 | R49: Claude(Fable5) | S49: 상 | T49: 미검토
A50: 49 | B50: RV-MANUAL-ENT-049 | C50: Manual | D50: RemoteView Enterprise SaaS 사용자 가이드 | E50: 사용자 별 에이전트 설치 수 제한 기능 > 엑셀 파일로 일괄등록 | F50: RemoteView | G50: 엑셀 파일로 일괄등록 | H50: 관리자 | I50: 공개 | J50: 설정/사용 방법 문의 | K50: https://files.rsupport.com/ko/remoteview/guides/RemoteView_Enterprise_SaaS_User_Guide_kr.pdf | L50: chunk 39 / §사용자 별 에이전트 설치 수 제한 기능 / ● 엑셀 파일로 일괄등록 | N50: ① [엑셀 파일로 일괄등록] 아이콘을 클릭합니다. <접근방법> 툴바 -> [엑셀 파일로 일괄등록] 버튼 클릭 ② 사용자 정보 일괄 등록 팝업 확인 ✔ [엑셀 양식 다운로드] : 사용자 정보 양식 .xlsx파일이 PC에 저장됩니다. ✔ [파일 선택] : Windows 파일 탐색기가 열립니다. ③ [등록] or [취소] 버튼을 클릭합니다. ✔ [등록] : 저장한 사용자 정보.xlsx파일이 등록됩니다. ✔ [취소] : 사용자 정보 일괄 등록 팝업 창이 닫힙니다. | O50: RemoteView에서 엑셀 파일로 일괄등록은(는) 어떻게 하나요? | P50: RemoteView, ENT, 엑셀 파일로 일괄등록 | Q50: RV-MANUAL-ENT-049 | R50: Claude(Fable5) | S50: 상 | T50: 미검토
A51: 50 | B51: RV-MANUAL-ENT-050 | C51: Manual | D51: RemoteView Enterprise SaaS 사용자 가이드 | E51: 사용자 별 에이전트 설치 수 제한 기능 > 소팅 | F51: RemoteView | G51: 소팅 | H51: 관리자 | I51: 공개 | J51: 기능/가능 여부 확인 | K51: https://files.rsupport.com/ko/remoteview/guides/RemoteView_Enterprise_SaaS_User_Guide_kr.pdf | L51: chunk 39 / §사용자 별 에이전트 설치 수 제한 기능 / ● 소팅 | N51: 전체보기/사용자 보기/그룹 보기의 옵션 값 대로 목록이 소팅 됩니다. | O51: RemoteView의 소팅은(는) 무엇인가요? | P51: RemoteView, ENT, 소팅 | Q51: RV-MANUAL-ENT-050 | R51: Claude(Fable5) | S51: 중 | T51: 미검토
A52: 51 | B52: RV-MANUAL-ENT-051 | C52: Manual | D52: RemoteView Enterprise SaaS 사용자 가이드 | E52: 사용자 별 에이전트 설치 수 제한 기능 > 소팅 | F52: RemoteView | G52: 소팅 | H52: 관리자 | I52: 공개 | J52: 기능/가능 여부 확인 | K52: https://files.rsupport.com/ko/remoteview/guides/RemoteView_Enterprise_SaaS_User_Guide_kr.pdf | L52: chunk 39 / §사용자 별 에이전트 설치 수 제한 기능 / ● 소팅 (2차) | N52: 선택한 옵션값대로 목록이 소팅 됩니다. | O52: RemoteView의 소팅은(는) 무엇인가요? | P52: RemoteView, ENT, 소팅 | Q52: RV-MANUAL-ENT-051 | R52: Claude(Fable5) | S52: 하 | T52: 근거약함 | U52: 본문 25자 미만 — 원문 근거 짧음
A53: 52 | B53: RV-MANUAL-ENT-052 | C53: Manual | D53: RemoteView Enterprise SaaS 사용자 가이드 | E53: 사용자 별 에이전트 설치 수 제한 기능 > 검색 | F53: RemoteView | G53: 검색 | H53: 관리자 | I53: 공개 | J53: 기능/가능 여부 확인 | K53: https://files.rsupport.com/ko/remoteview/guides/RemoteView_Enterprise_SaaS_User_Guide_kr.pdf | L53: chunk 39 / §사용자 별 에이전트 설치 수 제한 기능 / ● 검색 | N53: 입력한 검색어와 일치하는 데이터가 검색됩니다. | O53: RemoteView의 검색은(는) 무엇인가요? | P53: RemoteView, ENT, 검색 | Q53: RV-MANUAL-ENT-052 | R53: Claude(Fable5) | S53: 중 | T53: 미검토
A54: 53 | B54: RV-MANUAL-ENT-053 | C54: Manual | D54: RemoteView Enterprise SaaS 사용자 가이드 | E54: 사용자/조직관리 > 사용자 조직 > 새로고침 | F54: RemoteView | G54: 새로고침 | H54: 관리자 | I54: 공개 | J54: 설정/사용 방법 문의 | K54: https://files.rsupport.com/ko/remoteview/guides/RemoteView_Enterprise_SaaS_User_Guide_kr.pdf | L54: chunk 39 / §사용자/조직관리 > 사용자 조직 / ● 새로고침 | N54: ① [새로고침] 아이콘을 클릭합니다. ② 웹 페이지 화면의 데이터가 갱신됩니다. | O54: RemoteView에서 새로고침은(는) 어떻게 하나요? | P54: RemoteView, ENT, 새로고침 | Q54: RV-MANUAL-ENT-053 | R54: Claude(Fable5) | S54: 중 | T54: 미검토
A55: 54 | B55: RV-MANUAL-ENT-054 | C55: Manual | D55: RemoteView Enterprise SaaS 사용자 가이드 | E55: 사용자/조직관리 > 사용자 조직 > 매니저 추가 | F55: RemoteView | G55: 매니저 추가 | H55: 관리자 | I55: 공개 | J55: 설정/사용 방법 문의 | K55: https://files.rsupport.com/ko/remoteview/guides/RemoteView_Enterprise_SaaS_User_Guide_kr.pdf | L55: chunk 39 / §사용자/조직관리 > 사용자 조직 / ● 매니저 추가 | N55: ① [매니저 추가] 아이콘을 클릭합니다. <접근방법> 1 툴바 > [매니저 추가] 버튼 클릭 2 마우스 오른쪽 버튼 클릭 -> ‘매니저 추가’ 클릭 ② 사용자 정보를 입력합니다. ③ [적용] or [취소] 버튼을 클릭합니다. ✔ [적용] : 새로운 매니저가 추가됩니다. ✔ [취소] : 취소 | O55: RemoteView에서 매니저 추가은(는) 어떻게 하나요? | P55: RemoteView, ENT, 매니저 추가 | Q55: RV-MANUAL-ENT-054 | R55: Claude(Fable5) | S55: 상 | T55: 미검토
...

Sheet B1_근거약함
A1: Unit ID | B1: title | C1: source_location | D1: 상태 | E1: 비고 | F1: 이 단위가 말하는 사실(앞 150자)
A2: RV-MANUAL-ENT-029 | B2: RemoteView Enterprise SaaS 사용자 가이드 | C2: chunk 34 / §사용자별 제어 권한 / ● 소팅 | D2: 근거약함 | E2: 본문 25자 미만 — 원문 근거 짧음 | F2: 선택한 옵션값대로 목록이 소팅 됩니다.
A3: RV-MANUAL-ENT-038 | B3: RemoteView Enterprise SaaS 사용자 가이드 | C3: chunk 36 / §사용자별 제어 권한 / ● 소팅 | D3: 근거약함 | E3: 본문 25자 미만 — 원문 근거 짧음 | F3: 선택한 옵션값 대로 목록이 소팅 됩니다.
A4: RV-MANUAL-ENT-051 | B4: RemoteView Enterprise SaaS 사용자 가이드 | C4: chunk 39 / §사용자 별 에이전트 설치 수 제한 기능 / ● 소팅 (2차) | D4: 근거약함 | E4: 본문 25자 미만 — 원문 근거 짧음 | F4: 선택한 옵션값대로 목록이 소팅 됩니다.
A5: RV-MANUAL-ENT-061 | B5: RemoteView Enterprise SaaS 사용자 가이드 | C5: chunk 40 / §사용자/조직관리 > 사용자 조직 / ● 소팅 | D5: 근거약함 | E5: 본문 25자 미만 — 원문 근거 짧음 | F5: 선택한 옵션값 대로 목록이 소팅 됩니다.
A6: RV-MANUAL-ENT-067 | B6: RemoteView Enterprise SaaS 사용자 가이드 | C6: chunk 42 / §원격지원 이력 관리 / ● 원격제어 기능 설정 / ■ 모바일 접속 사용 | D6: 근거약함 | E6: 본문 25자 미만 — 원문 근거 짧음 | F6: 모바일 접속 여부를 설정합니다.
A7: RV-MANUAL-ENT-069 | B7: RemoteView Enterprise SaaS 사용자 가이드 | C7: chunk 42 / §원격지원 이력 관리 / ● 원격제어 기능 설정 / ■ 이메일 초대 | D7: 근거약함 | E7: 본문 25자 미만 — 원문 근거 짧음 | F7: 이메일 초대 기능 사용 여부를 설정합니다.
A8: RV-MANUAL-ENT-078 | B8: RemoteView Enterprise SaaS 사용자 가이드 | C8: chunk 42 / §원격지원 이력 관리 / ● 파일 전송 설정 / ■ 원격탐색기 사용 | D8: 근거약함 | E8: 본문 25자 미만 — 원문 근거 짧음 | F8: 원격탐색기 사용 여부를 설정합니다.
A9: RV-MANUAL-ENT-110 | B9: RemoteView Enterprise SaaS 사용자 가이드 | C9: chunk 50 / §내 옵션 설정 / ● 일반 설정 / ■ 즐겨찾기 | D9: 근거약함 | E9: 본문 25자 미만 — 원문 근거 짧음 | F9: 즐겨찾기 영역 사용여부를 설정합니다.
A10: RV-MANUAL-ENT-122 | B10: RemoteView Enterprise SaaS 사용자 가이드 | C10: chunk 51 / §RemoteView 정보 / ● 문의 | D10: 근거약함 | E10: 본문 25자 미만 — 원문 근거 짧음 | F10: 제품문의와 홈페이지의 링크가 제공됩니다.
A11: RV-MANUAL-ENT-127 | B11: RemoteView Enterprise SaaS 사용자 가이드 | C11: chunk 56 / §WOL로 전원 켜기 노출 조건 / ● Agent: Windows 대상 (그 외 OS 미노출) | D11: 근거약함 | E11: 본문 25자 미만 — 원문 근거 짧음 | F11: A B C
A12: RV-MANUAL-ENT-128 | B12: RemoteView Enterprise SaaS 사용자 가이드 | C12: chunk 64 / §등록정보 / ● 공유 폴더: 원격지 PC에서 전송받은 파일들이 저장되는 기본 폴더. 폴더의 | D12: 근거약함 | E12: 본문 25자 미만 — 원문 근거 짧음 | F12: 위치는 변경이 가능합니다.
... A27: RV-DOC-LEAF-002 | B27: RemoteView SE 리플렛 | C27: chunk 0 / §리플렛 / 리플렛 문단 2 | D27: 근거약함 | E27: 브로슈어 단문·OCR 품질 불안 (DEC-009 홍보 수사 정답 소재 금지 유의) | F27: R:SUPPORT ```

Sheet B1_사람확인
A1: Unit ID | B1: title | C1: source_location | D1: 상태 | E1: 비고 | F1: 이 단위가 말하는 사실(앞 150자)
A2: RV-MANUAL-ENT-066 | B2: RemoteView Enterprise SaaS 사용자 가이드 | C2: chunk 41 / §사용자/조직관리 > 사용자 조직 / ● 기간설정 | D2: 사람확인 | E2: 복합 내용 의심(절차+표 혼재 또는 과대 본문) — 재절단 검토 필요 | F2: ① Input-box 마우스 클릭합니다. ② 캘린더가 팝업 됩니다. ③ 시작일, 마지막일을 선택합니다. ④ [검색] 버튼을 클릭합니다. 환경설정 <각각의 권한 별 사용자에 맞게 설정을 할 수 있습니다.> 권한에 따라 로그인 시 사용할 수 있는 메뉴가 다릅니다. 관리자
A3: RV-MANUAL-ENT-134 | B3: RemoteView Enterprise SaaS 사용자 가이드 | C3: chunk 64 / §등록정보 / ● 리모트뷰 에이전트는 세션연결에 관한 정보를 에이전트가 설치 되어있는 PC에 저장합니다. 윈도우 우측 하단의 | D3: 사람확인 | E3: 복합 내용 의심(절차+표 혼재 또는 과대 본문) — 재절단 검토 필요 | F3: 아이콘 마우스 오른쪽 클릭 후 “로그 보기” 메뉴를 선택하여 로그 뷰어를 실행시켜 확인할 수 있습니다. 9. 리모트뷰 뷰어 기능 설명 뷰어 기능 요약 설명 홈 제어 설정 원격 접속 및 제어 환경을 설정 환경설정 제어 품질/모드, 미디어 장치 설정, 드라이버 설치 등의
A4: RV-MANUAL-IOSM-012 | B4: RemoteView SaaS 매뉴얼 iOS | C4: chunk 10 / §고객 지원 / ● 문의하기 | D4: 사람확인 | E4: 복합 내용 의심(절차+표 혼재 또는 과대 본문) — 재절단 검토 필요 | F4: ‘문의하기’ 메뉴 터치 시 문의등록 화면이 노출 됩니다. 필수 입력항목 (*이메일 주소/ 성명/ 회사명/ 전화번호/ 회사/사용자 ID/ 내용설명)을 모두 입력 후 개인정보 처리방침을 동의를 선택한 뒤에 ‘제출’하면 됩니다. (*첨부파일 기능은 모바일 기기에서는 사용할
A5: RV-MANUAL-AND-045 | B5: RemoteView Android SaaS 사용자 가이드 | C5: chunk 22 / §9.2 / ● 에이전트 등록 | D5: 사람확인 | E5: 복합 내용 의심(절차+표 혼재 또는 과대 본문) — 재절단 검토 필요 | F5: ① 홈페이지(https://rview.com/)에서 회원가입 시 등록한 계정으로 로그인합니다. ② 등록하고자 하는 대표아이디/사용자 아이디/비밀번호 입력 후 에이전트 등록 버튼을 선택 시 권한설정 페이지로 이동합니다. ③ 허용이 필요한 권한 > 권한설정으로 이동합니다.
A6: RV-DOC-LEAF-003 | B6: RemoteView SE 리플렛 | C6: chunk 0 / §리플렛 / 리플렛 문단 3 | D6: 사람확인 | E6: OCR 문자 역전 훼손 — 원본 PDF 대조 필요 | F6: 원격 제어 중 고객의 디바이스 네트워크 연결방식이 바뀌어도 원격 연결이 끊기지 않고 재연결 됩니다. 멀티 세션기능을 통한 동시 제어를 지원 합니다. 유지보수 및 장애 발생 시 서울에 집중되어 있는 IT 협력 업체의 지원을 안전하고 빠르게 받을 수 있어 비용과 장애처리

Sheet B1_제외대장
A1: Unit ID | B1: 사유
A2: (해당 없음 — B1 제외 단위 0. TOC·표지 청크 88개는 단위 미절단(목차는 사실 단위 아님), 본 보고 §비고 기재)

Sheet B1_폴딩대장
A1: Unit ID | B1: 사유
A2: (해당 없음 — 단일 작업자·단일 패스, dedup 미발화 정상(지시서 v0.4 §7))

Sheet B1_계리
A1: 항목 | B1: 값 | C1: 수식/근거
A2: 총 절단 단위 | B2: =COUNTA(B1_커버리지맵!B:B)-1 -> 444 | C2: 단위 시트 실측
A3: 미검토(유효) | B3: =COUNTIF(B1_커버리지맵!T:T,"미검토") -> 413
A4: 근거약함 | B4: =COUNTIF(B1_커버리지맵!T:T,"근거약함") -> 26 | C4: 대장 일치 필수
A5: 사람확인 | B5: =COUNTIF(B1_커버리지맵!T:T,"사람확인") -> 5 | C5: 대장 일치 필수
A6: 제외 | B6: =COUNTIF(B1_커버리지맵!T:T,"제외") -> 0
A7: 폴딩(중복) | B7: =COUNTIF(B1_커버리지맵!T:T,"중복") -> 0
A8: 등식 검증(합-총) | B8: =SUM(B3:B7)-B2 -> 0 | C8: 0이어야 함

Sheet B2_커버리지맵
A1: # | B1: Unit ID | C1: type | D1: title | E1: description | F1: product | G1: feature | H1: user_type | I1: acl_level | J1: intent | K1: source/resource | L1: source_location | M1: related_units | N1: 이 단위가 말하는 사실 | O1: 답변 가능한 질문 | P1: tags | Q1: citation_id | R1: extracted_by | S1: confidence | T1: 상태 | U1: 비고
A2: 1 | B2: RV-WEB-HOME-001 | C2: WebPage | D2: RemoteView 웹 홈 페이지 | E2: 국내 1위 원격제어 | F2: RemoteView | G2: 국내 1위 원격제어 | H2: 공통 | I2: 공개 | J2: 기능/제품 정보 확인 | K2: https://content.rview.com/ko/ | L2: 본문 § 국내 1위 원격제어 | N2: 리모트뷰는 다릅니다 끊김 없는 60FPS 제어 품질, SSO 로그인, 강화된 IP 보안까지 쾌적하고 안전한 업무 환경을 경험하세요. 최근 한달 1978명 체험 중 | O2: RemoteView 국내 1위 원격제어에 대해 알려주세요 | P2: RemoteView, 홈, 국내 1위 원격제어 | Q2: RV-WEB-HOME-001 | R2: Claude(Fable5) | S2: 상 | T2: 미검토
A3: 2 | B3: RV-WEB-HOME-002 | C3: WebPage | D3: RemoteView 웹 홈 페이지 | E3: 25년 연속 1위, | F3: RemoteView | G3: 25년 연속 1위, | H3: 공통 | I3: 공개 | J3: 기능/제품 정보 확인 | K3: https://content.rview.com/ko/ | L3: 본문 § 25년 연속 1위, | N3: 30만 고객이 선택한 리모트뷰 - ![기상청](/wp-content/uploads/sites/2/image/main/main_ranking_l - ![율촌](/wp-content/uploads/sites/2/image/main/main_ranking_ .webp) | O3: RemoteView 25년 연속 1위,에 대해 알려주세요 | P3: RemoteView, 홈, 25년 연속 1위, | Q3: RV-WEB-HOME-002 | R3: Claude(Fable5) | S3: 상 | T3: 미검토
A4: 3 | B4: RV-WEB-HOME-003 | C4: WebPage | D4: RemoteView 웹 홈 페이지 | E4: 원격으로 해결 가능한데, | F4: RemoteView | G4: 원격으로 해결 가능한데, | H4: 공통 | I4: 공개 | J4: 기능/제품 정보 확인 | K4: https://content.rview.com/ko/ | L4: 본문 § 원격으로 해결 가능한데, | N4: 아직도 현장에 가고 있나요? - 01 | O4: RemoteView 원격으로 해결 가능한데,에 대해 알려주세요 | P4: RemoteView, 홈, 원격으로 해결 가능한데, | Q4: RV-WEB-HOME-003 | R4: Claude(Fable5) | S4: 하 | T4: 근거약함 | U4: 본문 25자 미만
A5: 4 | B5: RV-WEB-HOME-004 | C5: WebPage | D5: RemoteView 웹 홈 페이지 | E5: 비용의 낭비 | F5: RemoteView | G5: 비용의 낭비 | H5: 공통 | I5: 공개 | J5: 기능/제품 정보 확인 | K5: https://content.rview.com/ko/ | L5: 본문 § 비용의 낭비 | N5: “서버 하나 재부팅하려고 IDC까지 왕복 4시간이나 걸렸어요.” 현장 출동 한 번에 드는 시간·운영비를 연간으로 환산하면 큰 비용입니다. - 02 | O5: RemoteView 비용의 낭비에 대해 알려주세요 | P5: RemoteView, 홈, 비용의 낭비 | Q5: RV-WEB-HOME-004 | R5: Claude(Fable5) | S5: 상 | T5: 미검토
A6: 5 | B6: RV-WEB-HOME-005 | C6: WebPage | D6: RemoteView 웹 홈 페이지 | E6: 업무 중단 | F6: RemoteView | G6: 업무 중단 | H6: 공통 | I6: 공개 | J6: 기능/제품 정보 확인 | K6: https://content.rview.com/ko/ | L6: 본문 § 업무 중단 | N6: “담당자가 출장 중이라 오후까지 기다려 주세요.” 장비 장애는 기다려주지 않습니다. 대응이 늦어지면 매출이 멈춥니다. - 03 | O6: RemoteView 업무 중단에 대해 알려주세요 | P6: RemoteView, 홈, 업무 중단 | Q6: RV-WEB-HOME-005 | R6: Claude(Fable5) | S6: 상 | T6: 미검토
A7: 6 | B7: RV-WEB-HOME-006 | C7: WebPage | D7: RemoteView 웹 홈 페이지 | E7: 보안·통제 부재 | F7: RemoteView | G7: 보안·통제 부재 | H7: 공통 | I7: 공개 | J7: 기능/제품 정보 확인 | K7: https://content.rview.com/ko/ | L7: 본문 § 보안·통제 부재 | N7: “외주 업체가 우리 서버에 접속했는데, 무엇을 했는지 모릅니다.” 접속 기록·화면 녹화·권한 통제가 없는 원격은 보안 사고의 시작입니다. | O7: RemoteView 보안·통제 부재에 대해 알려주세요 | P7: RemoteView, 홈, 보안·통제 부재 | Q7: RV-WEB-HOME-006 | R7: Claude(Fable5) | S7: 상 | T7: 미검토
A8: 7 | B8: RV-WEB-HOME-007 | C8: WebPage | D8: RemoteView 웹 홈 페이지 | E8: 어떤 현장이든, | F8: RemoteView | G8: 어떤 현장이든, | H8: 공통 | I8: 공개 | J8: 기능/제품 정보 확인 | K8: https://content.rview.com/ko/ | L8: 본문 § 어떤 현장이든, | N8: 목적에 맞는 원격제어 리모트뷰가 있습니다 [ | O8: RemoteView 어떤 현장이든,에 대해 알려주세요 | P8: RemoteView, 홈, 어떤 현장이든, | Q8: RV-WEB-HOME-007 | R8: Claude(Fable5) | S8: 하 | T8: 근거약함 | U8: 본문 25자 미만
A9: 8 | B9: RV-WEB-HOME-008 | C9: WebPage | D9: RemoteView 웹 홈 페이지 | E9: 리모트뷰 | F9: RemoteView | G9: 리모트뷰 | H9: 공통 | I9: 공개 | J9: 기능/제품 정보 확인 | K9: https://content.rview.com/ko/ | L9: 본문 § 리모트뷰 | N9: 웹 브라우저 하나로 언제 어디서든 내 PC 제어 ](/ko/product/remoteview/)[ | O9: RemoteView 리모트뷰에 대해 알려주세요 | P9: RemoteView, 홈, 리모트뷰 | Q9: RV-WEB-HOME-008 | R9: Claude(Fable5) | S9: 중 | T9: 미검토
A10: 9 | B10: RV-WEB-HOME-009 | C10: WebPage | D10: RemoteView 웹 홈 페이지 | E10: 리모트뷰 SE | F10: RemoteView | G10: 리모트뷰 SE | H10: 공통 | I10: 공개 | J10: 기능/제품 정보 확인 | K10: https://content.rview.com/ko/ | L10: 본문 § 리모트뷰 SE | N10: 외부 인력 접속 기록·권한 통제· 화면 차단까지, 강화된 보안 솔루션 ](/ko/product/remoteview-se/) [ | O10: RemoteView 리모트뷰 SE에 대해 알려주세요 | P10: RemoteView, 홈, 리모트뷰 SE | Q10: RV-WEB-HOME-009 | R10: Claude(Fable5) | S10: 상 | T10: 미검토
A11: 10 | B11: RV-WEB-HOME-010 | C11: WebPage | D11: RemoteView 웹 홈 페이지 | E11: 리모트뷰 OT | F11: RemoteView | G11: 리모트뷰 OT | H11: 공통 | I11: 공개 | J11: 기능/제품 정보 확인 | K11: https://content.rview.com/ko/ | L11: 본문 § 리모트뷰 OT | N11: 제조·산업 설비의 실시간 모니터링 및 즉시 대응 ](/ko/product/remoteview-ot/)[ | O11: RemoteView 리모트뷰 OT에 대해 알려주세요 | P11: RemoteView, 홈, 리모트뷰 OT | Q11: RV-WEB-HOME-010 | R11: Claude(Fable5) | S11: 중 | T11: 미검토
A12: 11 | B12: RV-WEB-HOME-011 | C12: WebPage | D12: RemoteView 웹 홈 페이지 | E12: AI 온라인 용역통제 시스템 | F12: RemoteView | G12: AI 온라인 용역통제 시스템 | H12: 공통 | I12: 공개 | J12: 기능/제품 정보 확인 | K12: https://content.rview.com/ko/ | L12: 본문 § AI 온라인 용역통제 시스템 | N12: 공공·금융 보안 기준을 충족하는 원격 용역 관리 체계 ](/ko/product/control/) [ | O12: RemoteView AI 온라인 용역통제 시스템에 대해 알려주세요 | P12: RemoteView, 홈, AI 온라인 용역통제 시스템 | Q12: RV-WEB-HOME-011 | R12: Claude(Fable5) | S12: 중 | T12: 미검토
A13: 12 | B13: RV-WEB-HOME-012 | C13: WebPage | D13: RemoteView 웹 홈 페이지 | E13: 리모트뷰박스 | F13: RemoteView | G13: 리모트뷰박스 | H13: 공통 | I13: 공개 | J13: 기능/제품 정보 확인 | K13: https://content.rview.com/ko/ | L13: 본문 § 리모트뷰박스 | N13: 소프트웨어 설치가 안되는 장비도 케이블 연결로 원격 제어 ](/ko/product/remoteviewbox/)[ | O13: RemoteView 리모트뷰박스에 대해 알려주세요 | P13: RemoteView, 홈, 리모트뷰박스 | Q13: RV-WEB-HOME-012 | R13: Claude(Fable5) | S13: 상 | T13: 미검토
A14: 13 | B14: RV-WEB-HOME-013 | C14: WebPage | D14: RemoteView 웹 홈 페이지 | E14: RemoteWOL | F14: RemoteView | G14: RemoteWOL | H14: 공통 | I14: 공개 | J14: 기능/제품 정보 확인 | K14: https://content.rview.com/ko/ | L14: 본문 § RemoteWOL | N14: 퇴근 후에도 클릭 한 번으로 PC·서버 전원을 제어, 상시 가동 비용 절감 ](/ko/product/remotewol/) 나에게 맞는 리모트뷰 제품 찾기 나에게 맞는 리모트뷰 제품 찾기 ![](/wp-content/uploads/sites/2/image/main/main_popup_icon.webp) 리모트뷰 제품 라인업 한 눈에 비교하기 ➡️ 리모트뷰는 도입 방식과 기능에 따라 다양한 제품 라인업을 제공합니다. ✔️ 여러분의 비즈니스에 맞는 최적의 제품을 찾아보세요. 🔍 리모트뷰 제품 라인업 | 구분 | 구독형(SaaS) | 구축형(솔루션) | 하드웨어형 | | --- | --- | --- | --- | | 리모트뷰 제품 라인업 | - 리모트뷰 : 가장 범용적으로 사용하는 원격제어 솔루션 (원격제어, 재택근무 등) | - 리모트뷰SE : 보안강화형 - 리모트뷰OT : 제조업 특화형 - 온라인 용역 통제솔루션 : 공공기관 특화 용역 및 장비관리 | - RemoteViewBOX : 보안이슈 또는 노후장비로 에이전트 설치가 어려운 장치를 케이블로 연결 - RemoteWOL : PC와 서버의 전원 원격제어 | | 도입방식 | 온라인에서 구매 후 바로 사용 가능 | 상담 후 적용 / 기업이나 기관 환경에 맞는 다양한 솔루션 구축방식 제공 | 구매 후 설치하여 사용 가능 | | 기능 | - 모바일 원격제어 - 웹뷰어 - 다중접속 기능 - 멀티/듀얼모니터 - 원격PC 화면잠금 - 원격프린터 - 특정 프로세스 실행제한 - 특정도메인 차단 - OTP인증 등 - 원격제어 기능 제공 | 리모트뷰 기능 전체 + 보안 및 비즈니스 특화 / 보안 요구사항 및 비즈니스 요구사항 충족하여 커스텀 개발 | - RemoteViewBOX : 리모트뷰 기능 그대로 사용 / 노후기기·특수기기 등에 케이블로 연결하여 원격제어 가능 - RemoteWOL : 리모트뷰가 설치된 PC·서버 등 다수의 디바이스 전원을 원격으로 통제 | | 가격 | - 스탠다드 월 5,000원 - 엔터프라이즈 월 7,000원 \*연간 결제 시 할인적용[자세히보기](/ko/pricing/license/) | 서버 / 솔루션 / 어플라이언스 / 구축형 클라우 드 등 환경·사양에 따라 다양 [문의하기](/ko/contact/) | - RemoteViewBOX : 1,000,000원 / 1EA - RemoteWOL : 500,000원 / 1EA | 💡 리모트뷰, 직접 경험하며 선택해 보세요. ✅ 도움이 필요하시다면 편하게 상담을 신청해 주세요. [문의하기](/ko/contact/) ✅ 상담 전, 리모트뷰를 직접 체험해보시는 것 도 좋아요. [무료로 이용하기](/ko/trial/) | O14: RemoteView RemoteWOL에 대해 알려주세요 | P14: RemoteView, 홈, RemoteWOL | Q14: RV-WEB-HOME-013 | R14: Claude(Fable5) | S14: 상 | T14: 미검토
A15: 14 | B15: RV-WEB-HOME-014 | C15: WebPage | D15: RemoteView 웹 홈 페이지 | E15: PC 원격제어 | F15: RemoteView | G15: PC 원격제어 | H15: 공통 | I15: 공개 | J15: 기능/제품 정보 확인 | K15: https://content.rview.com/ko/ | L15: 본문 § PC 원격제어 | N15: 운영체제 상관없이 간편하게 PC를 원격제어 ](/ko/feature) | O15: RemoteView PC 원격제어에 대해 알려주세요 | P15: RemoteView, 홈, PC 원격제어 | Q15: RV-WEB-HOME-014 | R15: Claude(Fable5) | S15: 중 | T15: 미검토
A16: 15 | B16: RV-WEB-HOME-015 | C16: WebPage | D16: RemoteView 웹 홈 페이지 | E16: 모바일 원격제어 | F16: RemoteView | G16: 모바일 원격제어 | H16: 공통 | I16: 공개 | J16: 기능/제품 정보 확인 | K16: https://content.rview.com/ko/ | L16: 본문 § 모바일 원격제어 | N16: 리모트뷰 앱으로 스마트폰에서 PC 제어 ](/ko/feature/mobile/) | O16: RemoteView 모바일 원격제어에 대해 알려주세요 | P16: RemoteView, 홈, 모바일 원격제어 | Q16: RV-WEB-HOME-015 | R16: Claude(Fable5) | S16: 중 | T16: 미검토
A17: 16 | B17: RV-WEB-HOME-016 | C17: WebPage | D17: RemoteView 웹 홈 페이지 | E17: 웹뷰어 제어 | F17: RemoteView | G17: 웹뷰어 제어 | H17: 공통 | I17: 공개 | J17: 기능/제품 정보 확인 | K17: https://content.rview.com/ko/ | L17: 본문 § 웹뷰어 제어 | N17: 설치 없이 브라우저에서 바로 접속·제어 ](/ko/feature/webviewer/) | O17: RemoteView 웹뷰어 제어에 대해 알려주세요 | P17: RemoteView, 홈, 웹뷰어 제어 | Q17: RV-WEB-HOME-016 | R17: Claude(Fable5) | S17: 중 | T17: 미검토
A18: 17 | B18: RV-WEB-HOME-017 | C18: WebPage | D18: RemoteView 웹 홈 페이지 | E18: 다중접속 기능 | F18: RemoteView | G18: 다중접속 기능 | H18: 공통 | I18: 공개 | J18: 기능/제품 정보 확인 | K18: https://content.rview.com/ko/ | L18: 본문 § 다중접속 기능 | N18: 여러 사용자 동시 접속, 실시간 협업 ](/ko/feature/multiple-access/) | O18: RemoteView 다중접속 기능에 대해 알려주세요 | P18: RemoteView, 홈, 다중접속 기능 | Q18: RV-WEB-HOME-017 | R18: Claude(Fable5) | S18: 중 | T18: 미검토
A19: 18 | B19: RV-WEB-HOME-018 | C19: WebPage | D19: RemoteView 웹 홈 페이지 | E19: 멀티/듀얼모니터 | F19: RemoteView | G19: 멀티/듀얼모니터 | H19: 공통 | I19: 공개 | J19: 기능/제품 정보 확인 | K19: https://content.rview.com/ko/ | L19: 본문 § 멀티/듀얼모니터 | N19: 다중 모니터 자유 전환, 원격 멀티태스킹 ](/ko/feature/multiple-monitors/) | O19: RemoteView 멀티/듀얼모니터에 대해 알려주세요 | P19: RemoteView, 홈, 멀티/듀얼모니터 | Q19: RV-WEB-HOME-018 | R19: Claude(Fable5) | S19: 중 | T19: 미검토
A20: 19 | B20: RV-WEB-HOME-019 | C20: WebPage | D20: RemoteView 웹 홈 페이지 | E20: 실시간 모니터링(라이브뷰) | F20: RemoteView | G20: 실시간 모니터링(라이브뷰) | H20: 공통 | I20: 공개 | J20: 기능/제품 정보 확인 | K20: https://content.rview.com/ko/ | L20: 본문 § 실시간 모니터링(라이브뷰) | N20: 5초 단위 라이브뷰, 제어 없이 상태 확인 ](/ko/feature) | O20: RemoteView 실시간 모니터링(라이브뷰)에 대해 알려주세요 | P20: RemoteView, 홈, 실시간 모니터링(라이브뷰) | Q20: RV-WEB-HOME-019 | R20: Claude(Fable5) | S20: 중 | T20: 미검토
A21: 20 | B21: RV-WEB-HOME-020 | C21: WebPage | D21: RemoteView 웹 홈 페이지 | E21: 국가·국제 보안 인증 기준을 충족한 기술로 | F21: RemoteView | G21: 국가·국제 보안 인증 기준을 충족한 기술로 | H21: 공통 | I21: 공개 | J21: 기능/제품 정보 확인 | K21: https://content.rview.com/ko/ | L21: 본문 § 국가·국제 보안 인증 기준을 충족한 기술로 | N21: 안정적인 원격제어 환경을 제공합니다 안전한 원격제어를 위해 검증된 보안 체계를 제공합니다 브라우저가 video 태그를 지원하지 않습니다. | O21: RemoteView 국가·국제 보안 인증 기준을 충족한 기술로에 대해 알려주세요 | P21: RemoteView, 홈, 국가·국제 보안 인증 기준을 충족한 | Q21: RV-WEB-HOME-020 | R21: Claude(Fable5) | S21: 상 | T21: 미검토
A22: 21 | B22: RV-WEB-HOME-021 | C22: WebPage | D22: RemoteView 웹 홈 페이지 | E22: 국가 공인 | F22: RemoteView | G22: 국가 공인 | H22: 공통 | I22: 공개 | J22: 기능/제품 정보 확인 | K22: https://content.rview.com/ko/ | L22: 본문 § 국가 공인 | N22: 최고 등급 품질 인증 GS인증 1등급으로 제품의 품질, 기능성, 사용성을 공인된 기준으로 검증받았습니다. GS인증 1등급 한국정보통신기술협회 1등급 품질 인증 기능, 품질, 사용성을 공인 시험 기준으로 검증한 소프트웨어입니다. 공공 및 기업 환경에서 신뢰할 수 있 는 품질 수준을 제공합니다. 브라우저가 video 태그를 지원하지 않습니다. | O22: RemoteView 국가 공인에 대해 알려주세요 | P22: RemoteView, 홈, 국가 공인 | Q22: RV-WEB-HOME-021 | R22: Claude(Fable5) | S22: 상 | T22: 미검토 | U22: DEC-009 유의(홍보성 표현 포함) — 정답 소재 금지
A23: 22 | B23: RV-WEB-HOME-022 | C23: WebPage | D23: RemoteView 웹 홈 페이지 | E23: 국제 최고 수준 | F23: RemoteView | G23: 국제 최고 수준 | H23: 공통 | I23: 공개 | J23: 기능/제품 정보 확인 | K23: https://content.rview.com/ko/ | L23: 본문 § 국제 최고 수준 | N23: 정보보호 관리체계 인증 ISO/IEC 27001:2022, ISO/IEC 27017:2015 인증을 기반으로 국제 기준의 정보보호 관리체계를 준수하고 있습니다. ISO/IEC 27001:2022 ISO/IEC 27017:2015 정보보안 국제인증 국제 기준의 정보보호 관리체계를 준수하고 있습니다. 보안 정책부터 운영 관리까지 체계적인 보안 환경을 기반으로 서비스를 제공합니다. 브라우저가 video 태그를 지원하지 않습니다. | O23: RemoteView 국제 최고 수준에 대해 알려주세요 | P23: RemoteView, 홈, 국제 최고 수준 | Q23: RV-WEB-HOME-022 | R23: Claude(Fable5) | S23: 상 | T23: 미검토
A24: 23 | B24: RV-WEB-HOME-023 | C24: WebPage | D24: RemoteView 웹 홈 페이지 | E24: 공공 조달 등록으로 | F24: RemoteView | G24: 공공 조달 등록으로 | H24: 공통 | I24: 공개 | J24: 기능/제품 정보 확인 | K24: https://content.rview.com/ko/ | L24: 본문 § 공공 조달 등록으로 | N24: 검증된 제품 조달청 등록으로 공공기관 도입 기준을 충족한 검증된 제품입니다. 조달청 등록제품 국가정보원 국가정보보안기본지침 준수 공공기관이 요구하는 등록 기준과 절차를 충족한 제품입니다. 공공 도입 과정에서 요구되는 검증을 완료한 신뢰할 수 있는 제품입니다. 브라우저가 video 태그를 지원하지 않습니다. | O24: RemoteView 공공 조달 등록으로에 대해 알려주세요 | P24: RemoteView, 홈, 공공 조달 등록으로 | Q24: RV-WEB-HOME-023 | R24: Claude(Fable5) | S24: 상 | T24: 미검토
A25: 24 | B25: RV-WEB-HOME-024 | C25: WebPage | D25: RemoteView 웹 홈 페이지 | E25: 도입 기준에 대한 | F25: RemoteView | G25: 도입 기준에 대한 | H25: 공통 | I25: 공개 | J25: 기능/제품 정보 확인 | K25: https://content.rview.com/ko/ | L25: 본문 § 도입 기준에 대한 | N25: 신속한 검증 KISA 신속확인제를 통해 공공 및 기업의 도입 전 보안 검토를 신속하게 진행할 수 있습니다. KISA 신속확인제 공공기관 정보보호제품 도입 보안성 검증 공공기관 정보보호제품 도입 시 필요한 보안 적합성을 사전에 확인받았습니다. 도입 검토 과정에서 요구되는 보안 검토 부담을 줄일 수 있습니다. 브라우저가 video 태그를 지원하지 않습니다. | O25: RemoteView 도입 기준에 대한에 대해 알려주세요 | P25: RemoteView, 홈, 도입 기준에 대한 | Q25: RV-WEB-HOME-024 | R25: Claude(Fable5) | S25: 상 | T25: 미검토
A26: 25 | B26: RV-WEB-HOME-025 | C26: WebPage | D26: RemoteView 웹 홈 페이지 | E26: 국가 기준으로 검증된 | F26: RemoteView | G26: 국가 기준으로 검증된 | H26: 공통 | I26: 공개 | J26: 기능/제품 정보 확인 | K26: https://content.rview.com/ko/ | L26: 본문 § 국가 기준으로 검증된 | N26: 암호 안전성 국가정보원 KCMVP 인증을 통해 국가·공공기관 도입에 필요한 암호모듈 검증을 완료했습니다. 국가정보 KCMVP 국가·공공기관 도입 필수 암호모듈 안전성 확보 국가·공공 환경에서 요구되는 기준을 충족한 암호모듈을 적용했습니다. 검증된 암호모듈을 기반으로 강화된 보안 환경을 제공합니다. 안정적인 서비스 제공을 위해 명확한 서비스 수준협약(SLA)을 수립·준수하고 있습니다. 약속된 품질 기준을 확인해 보세요. | O26: RemoteView 국가 기준으로 검증된에 대해 알려주세요 | P26: RemoteView, 홈, 국가 기준으로 검증된 | Q26: RV-WEB-HOME-025 | R26: Claude(Fable5) | S26: 상 | T26: 미검토
A27: 26 | B27: RV-WEB-HOME-026 | C27: WebPage | D27: RemoteView 웹 홈 페이지 | E27: 이미 30만 기업이 리모트뷰로 | F27: RemoteView | G27: 이미 30만 기업이 리모트뷰로 | H27: 공통 | I27: 공개 | J27: 기능/제품 정보 확인 | K27: https://content.rview.com/ko/ | L27: 본문 § 이미 30만 기업이 리모트뷰로 | N27: 확실한 변화를 경험하고 있습니다 리모트뷰 고객사 평가기준 - ### 1위 25년 연속 원격 솔루션 1위 - ### 80% 시스템 유지보수 비용 절감 - ### 72% 인력 파견빈도 감소 - ### 83% 고객 만족도 (제품 사용편의성 포함) | O27: RemoteView 이미 30만 기업이 리모트뷰로에 대해 알려주세요 | P27: RemoteView, 홈, 이미 30만 기업이 리모트뷰로 | Q27: RV-WEB-HOME-026 | R27: Claude(Fable5) | S27: 상 | T27: 미검토 | U27: DEC-009 유의(홍보성 표현 포함) — 정답 소재 금지
A28: 27 | B28: RV-WEB-HOME-027 | C28: WebPage | D28: RemoteView 웹 홈 페이지 | E28: 운영비 30% 절감, | F28: RemoteView | G28: 운영비 30% 절감, | H28: 공통 | I28: 공개 | J28: 기능/제품 정보 확인 | K28: https://content.rview.com/ko/ | L28: 본문 § 운영비 30% 절감, | N28: 서비스 안정성은 강화 “리모트뷰 도입 후 무인매장 운영 비용이 기존 대비 30% 이상 절감되고, 안정적인 서비스 운영으로 점주와 고객 만족도가 높아졌습니다.” ![인생네컷](/wp-content/uploads/sites/2/image/main/main_ranking_review_02.webp) 무인기기 ](</ko/cases/equipment-03/ >)[![현장 대응 부담 절감, 원격 관리 체계 강화](/wp-content/uploads/sites/2/image/main/main_review_02.webp) | O28: RemoteView 운영비 30% 절감,에 대해 알려주세요 | P28: RemoteView, 홈, 운영비 30% 절감, | Q28: RV-WEB-HOME-027 | R28: Claude(Fable5) | S28: 상 | T28: 미검토
A29: 28 | B29: RV-WEB-HOME-028 | C29: WebPage | D29: RemoteView 웹 홈 페이지 | E29: 현장 대응 부담 절감, | F29: RemoteView | G29: 현장 대응 부담 절감, | H29: 공통 | I29: 공개 | J29: 기능/제품 정보 확인 | K29: https://content.rview.com/ko/ | L29: 본문 § 현장 대응 부담 절감, | N29: 원격 관리 체계 강화 “리모트뷰 솔루션 구축으로 전국 사업장과 외주 용역을 원격 관리하며, 대응과 관리 데이터를 혁신했습니다.” ![한국환경공단](/wp-content/uploads/sites/2/image/main/main_ranking_review_01.webp) 공공기관 ](/ko/cases/institution-03/) | O29: RemoteView 현장 대응 부담 절감,에 대해 알려주세요 | P29: RemoteView, 홈, 현장 대응 부담 절감, | Q29: RV-WEB-HOME-028 | R29: Claude(Fable5) | S29: 상 | T29: 미검토
A30: 29 | B30: RV-WEB-HOME-029 | C30: WebPage | D30: RemoteView 웹 홈 페이지 | E30: 리모트뷰의 다양한 소식을 | F30: RemoteView | G30: 리모트뷰의 다양한 소식을 | H30: 공통 | I30: 공개 | J30: 기능/제품 정보 확인 | K30: https://content.rview.com/ko/ | L30: 본문 § 리모트뷰의 다양한 소식을 | N30: 블로그로 만나보세요 인사이트 | O30: RemoteView 리모트뷰의 다양한 소식을에 대해 알려주세요 | P30: RemoteView, 홈, 리모트뷰의 다양한 소식을 | Q30: RV-WEB-HOME-029 | R30: Claude(Fable5) | S30: 하 | T30: 근거약함 | U30: 본문 25자 미만
A31: 30 | B31: RV-WEB-HOME-030 | C31: WebPage | D31: RemoteView 웹 홈 페이지 | E31: 13시간 주식 거래와 망분리 완화, 증권사 재택근무가 필수 인프라가 된 3가지 배경 | F31: RemoteView | G31: 13시간 주식 거래와 망분리 완화, 증권사 재택근무가 필수 인프라가 된 | H31: 공통 | I31: 공개 | J31: 기능/제품 정보 확인 | K31: https://content.rview.com/ko/ | L31: 본문 § 13시간 주식 거래와 망분리 완화, 증권사 재택근무가 필수 인프라가 된 | N31: ](https://content.rview.com/ko/blog/securities-firm-remote-work-compliance/) 활용팁 | O31: RemoteView 13시간 주식 거래와 망분리 완화, 증권사 재택근무가 에 대해 알려주세요 | P31: RemoteView, 홈, 13시간 주식 거래와 망분리 완화, | Q31: RV-WEB-HOME-030 | R31: Claude(Fable5) | S31: 상 | T31: 미검토
A32: 31 | B32: RV-WEB-HOME-031 | C32: WebPage | D32: RemoteView 웹 홈 페이지 | E32: 네이트온 원격제어: 리모트뷰를 찾는다면? 14일 무료 체험 및 퀵 사용 가이드 | F32: RemoteView | G32: 네이트온 원격제어: 리모트뷰를 찾는다면? 14일 무료 체험 및 퀵 사용 | H32: 공통 | I32: 공개 | J32: 기능/제품 정보 확인 | K32: https://content.rview.com/ko/ | L32: 본문 § 네이트온 원격제어: 리모트뷰를 찾는다면? 14일 무료 체험 및 퀵 사용 | N32: ](https://content.rview.com/ko/blog/nateon-remoteview-guide-and-free-trial/) 자료 | O32: RemoteView 네이트온 원격제어: 리모트뷰를 찾는다면? 14일 무료 에 대해 알려주세요 | P32: RemoteView, 홈, 네이트온 원격제어: 리모트뷰를 찾는다 | Q32: RV-WEB-HOME-031 | R32: Claude(Fable5) | S32: 상 | T32: 미검토
A33: 32 | B33: RV-WEB-HOME-032 | C33: WebPage | D33: RemoteView 웹 홈 페이지 | E33: RDP 원격 데스크톱 연결 및 VNC 사용법 완벽 가이드: | F33: RemoteView | G33: RDP 원격 데스크톱 연결 및 VNC 사용법 완벽 가이드: | H33: 공통 | I33: 공개 | J33: 기능/제품 정보 확인 | K33: https://content.rview.com/ko/ | L33: 본문 § RDP 원격 데스크톱 연결 및 VNC 사용법 완벽 가이드: | N33: 3389 포트 설정보다 중요한 실무 보안의 모든 것 ](https://content.rview.com/ko/blog/rdp-vnc-remote-desktop-security/) | O33: RemoteView RDP 원격 데스크톱 연결 및 VNC 사용법 완벽 가이에 대해 알려주세요 | P33: RemoteView, 홈, RDP 원격 데스크톱 연결 및 VNC | Q33: RV-WEB-HOME-032 | R33: Claude(Fable5) | S33: 상 | T33: 미검토
A34: 33 | B34: RV-WEB-HOME-033 | C34: WebPage | D34: RemoteView 웹 홈 페이지 | E34: 구독형 제품 | F34: RemoteView | G34: 구독형 제품 | H34: 공통 | I34: 공개 | J34: 기능/제품 정보 확인 | K34: https://content.rview.com/ko/ | L34: 본문 § 구독형 제품 | N34: 월 결제로 부담없이 시작 14일 무료체험으로 먼저 써보고, 도입 여부를 결정하세요. | O34: RemoteView 구독형 제품에 대해 알려주세요 | P34: RemoteView, 홈, 구독형 제품 | Q34: RV-WEB-HOME-033 | R34: Claude(Fable5) | S34: 중 | T34: 미검토
A35: 34 | B35: RV-WEB-HOME-034 | C35: WebPage | D35: RemoteView 웹 홈 페이지 | E35: 구축형 제품 | F35: RemoteView | G35: 구축형 제품 | H35: 공통 | I35: 공개 | J35: 기능/제품 정보 확인 | K35: https://content.rview.com/ko/ | L35: 본문 § 구축형 제품 | N35: 기업 환경에 맞춘 전용 시스템 구축 전문 컨설턴트가 환경에 맞는 구축 방법과 비용을 1:1로 안내해 드립니다. 브라우저가 video 태그를 지원하지 않습니다. | O35: RemoteView 구축형 제품에 대해 알려주세요 | P35: RemoteView, 홈, 구축형 제품 | Q35: RV-WEB-HOME-034 | R35: Claude(Fable5) | S35: 상 | T35: 미검토
A36: 35 | B36: RV-WEB-HOME-035 | C36: WebPage | D36: RemoteView 웹 홈 페이지 | E36: 업무에 도움이 되는 알짜레터를 받아보세요 | F36: RemoteView | G36: 업무에 도움이 되는 알짜레터를 받아보세요 | H36: 공통 | I36: 공개 | J36: 기능/제품 정보 확인 | K36: https://content.rview.com/ko/ | L36: 본문 § 업무에 도움이 되는 알짜레터를 받아보세요 | N36: \[필수\] 만 14세 이상이며, 개인정보 수집 및 이용에 동의합니다. \[선택\] 이벤트, 프로모션 등 마케팅 정보 수신에 동의합니다. 알짜레터 구독하기 개인정보 수집 및 이용 안내문 ∙ 수집하는 항목 : (필수)이메일 ∙ 수집 및 이용목적 : 알짜레터 발송 ∙ 보유 및 이용기간 : 구독해지 시 까지 - ※ 개인정보 수집 및 이용에 대한 동의를 거부할 권리가 있습니다. 그러나 동의를 거부할 경우, 알짜레터를 받아보실 수 없습니다. 닫기 마케팅 정보 수신 동의 안내문 - ※ 마케팅 정보 수신에 대한 동의를 거부할 수 있습니다. 그러나 동의하지 않을 경우 편의 제공 안내 등 이용 목적에 따른 혜택에 제한이 있을 수 있습니다. - ※ 마케팅 정보를 더 이상 받고 싶지 않으실 경우, 이메일 하단의 수신거부를 통해 철회요청 하시기 바랍니다. 닫기 Go to Top App DownLoad - Android App **알서포트(주)** 대표 : 서형수 주소 : (05203) 서울특별시 강동구 고덕비즈밸리로2가길 12 (고덕동) Windows® is a trademark of the Microsoft group of companies. iPhone® and iPad® are trademarks of Apple Inc., registered in the U.S. and other countries. Android™ is a trademark of Google Inc. © [RSUPPORT](https://www.rsupport.com/) CO., LTD. ALL RIGHTS RESERVED. [ 문의하기 ](https://help.rview.com/hc/ko/requests/new?ticket_form_id=360000030893)[ 시작가이드 ](/ko/support/tutorial/)[ 10분 체험 ](https://rview.com/ko/virtual_exp) | O36: RemoteView 업무에 도움이 되는 알짜레터를 받아보세요에 대해 알려주세요 | P36: RemoteView, 홈, 업무에 도움이 되는 알짜레터를 받아보 | Q36: RV-WEB-HOME-035 | R36: Claude(Fable5) | S36: 상 | T36: 미검토
A37: 36 | B37: RV-WEB-MISC-001 | C37: WebPage | D37: RemoteView 웹 B0편입 페이지 | E37: (도입부) | F37: RemoteView | G37: (도입부) | H37: 공통 | I37: 공개 | J37: 기능/제품 정보 확인 | K37: https://content.rview.com/ko/?p=13953 | L37: 본문 § (도입부) | N37: 리모트뷰 라이선스 구매 **구매를 위해 리모트뷰 로그인 페이지로 이동하세요.** 리모트뷰 계정으로 로그인하시면 즉시 라이선스 구매가 가능합니다. **리모트뷰 계정이 없으시다면? >** 지금 바로 [계정을 생성하고 2주간 무료로](/ko/trial/) 이용하세요!! **로그인전 리모트뷰 온라인 구매 가이드를 확인하세요!** 서비스 로그인 리모트뷰에 로그인 합니다. 리모트뷰 계정이 없다면, 가입하여 계정을 생성합니다. 결제 메뉴 클릭 서비스 페이지의 상단의 “결제” 메뉴로 이동합니다. 유료 전환 클릭 회원가입 시 발급된 데모 라이선스를 유료 전환합니다. 구매 정보 입력 후 결제 구매 기간/ 라이선스 종류/ PC수를 선택한 후 결제를 진행합니다. - ※상기의 구입 안내 절차는 표준 모드에서만 동작하는 화면입니다. - ※심플모드를 이용중인 분은 아래의 방법을 진행하신 후 표준화면으로 이동하여 위 2~4로 진행할 수 있습니다. 메뉴 아이콘 클릭 심플모드인 경우 메뉴아이콘을 클릭합니다. 메뉴\[환경설정\]을 선택 메뉴\[환경설정\]을 선택하여 환경설정페이지로 진입합니다. Go to Top App DownLoad - Android App **알서포트(주)** 대표 : 서형수 주소 : (05203) 서울특별시 강동구 고덕비즈밸리로2가길 12 (고덕동) Windows® is a trademark of the Microsoft group of companies. iPhone® and iPad® are trademarks of Apple Inc., registered in the U.S. and other countries. Android™ is a trademark of Google Inc. © [RSUPPORT](https://www.rsupport.com/) CO., LTD. ALL RIGHTS RESERVED. [ 문의하기 ](https://help.rview.com/hc/ko/requests/new?ticket_form_id=360000030893)[ 시작가이드 ](/ko/support/tutorial/)[ 10분 체험 ](https://rview.com/ko/virtual_exp) | O37: RemoteView (도입부)에 대해 알려주세요 | P37: RemoteView, B0편입, (도입부) | Q37: RV-WEB-MISC-001 | R37: Claude(Fable5) | S37: 상 | T37: 미검토
